[2022-03-14 06:46:39,522 |   INFO   | user_metadata] Starting
[2022-03-14 06:46:39,523 |   INFO   | user_metadata] Loaded 1498 usernames
[2022-03-14 06:46:39,524 |   INFO   | user_metadata] Getting metadata for 0x482914ce89836db864987707ac8d96e965419efc
[2022-03-14 06:46:41,943 |   INFO   | user_metadata] Getting metadata for 0xe7079eec020ddfc3f1c0abe1d946c55e6ed30eb3
[2022-03-14 06:46:45,934 |   INFO   | user_metadata] Getting metadata for 0x8bbc693d042cea740e4ff01d7e0efb36110c36bf
[2022-03-14 06:46:48,270 |   INFO   | user_metadata] Getting metadata for 0xc3f733ca98e0dad0386979eb96fb1722a1a05e69
[2022-03-14 06:46:49,939 |   INFO   | user_metadata] Getting metadata for 0x29ebde3010cb23bac83b3cc4dd059a78317305fe
[2022-03-14 06:46:52,024 |   INFO   | user_metadata] Getting metadata for 0x97916e27632ec5f1f4c549ba7bf4c8850344a32b
[2022-03-14 06:46:54,933 |   INFO   | user_metadata] Getting metadata for 0xf8c75c5e9ec6875c57c0dbc30b59934b37908c4e
[2022-03-14 06:46:58,239 |   INFO   | user_metadata] Getting metadata for 0x69b47e91e2eea2525770ed93f6115b9d8f4fa132
[2022-03-14 06:47:00,411 |   INFO   | user_metadata] Getting metadata for 0xabeffb353dae4a177057e9a3e4a663386cf54758
[2022-03-14 06:47:03,744 |   INFO   | user_metadata] Getting metadata for 0x50dd57f50a17d57304e7a4f262da30beb31c2e87
[2022-03-14 06:47:06,880 |   INFO   | user_metadata] Getting metadata for 0x54be3a794282c030b15e43ae2bb182e14c409c5e
[2022-03-14 06:47:10,872 |   INFO   | user_metadata] Getting metadata for 0x08797952462b82db639ddbfdef2ab1718ffa7676
[2022-03-14 06:47:15,897 |   INFO   | user_metadata] Getting metadata for 0x2de14db256db2597fe3c8eed46ef5b20ba390823
[2022-03-14 06:47:18,614 |   INFO   | user_metadata] Getting metadata for 0x8bc1e2e9cf5dab703f8252473cbbdaef83843f95
[2022-03-14 06:47:21,178 |   INFO   | user_metadata] Getting metadata for 0x9af756e7be065dca83674ec17f3703579a544da1
[2022-03-14 06:47:24,194 |   INFO   | user_metadata] Getting metadata for 0x8c685c44facb8bf246fcb0e383cca4bd46634bf8
[2022-03-14 06:47:26,424 |   INFO   | user_metadata] Getting metadata for 0x9edf9b08406fa69a9dd5f73269f8a927b4f772d7
[2022-03-14 06:47:29,354 |   INFO   | user_metadata] Getting metadata for 0x7eb413211a9de1cd2fe8b8bb6055636c43f7d206
[2022-03-14 06:47:32,703 |   INFO   | user_metadata] Getting metadata for 0x58cd128282d652a6d14d93d68b416db414ee2962
[2022-03-14 06:47:34,913 |   INFO   | user_metadata] Getting metadata for 0xb5696e4057b9ba76616cecb5a537eaca7b3cdf54
[2022-03-14 06:47:37,628 |   INFO   | user_metadata] Getting metadata for 0xf7afb2d272bcb74f54b631d56982ee9f649acd70
[2022-03-14 06:47:40,237 |   INFO   | user_metadata] Getting metadata for 0x2206168cde2b3652e2488d9a1283531a4d200aea
[2022-03-14 06:47:42,271 |   INFO   | user_metadata] Getting metadata for 0xd9d1c2623fbb4377d9bf29075e610a9b8b4805b4
[2022-03-14 06:47:46,384 |   INFO   | user_metadata] Getting metadata for 0x5b20783f4baabd33bb53dd77c9b0459f5701e36a
[2022-03-14 06:47:49,939 |   INFO   | user_metadata] Getting metadata for 0x19ac63521615455415a716f5dcbb49d065ae8092
[2022-03-14 06:47:53,278 |   INFO   | user_metadata] Getting metadata for 0x68b42e44079d1d0a4a037e8c6ecd62c48967e69f
[2022-03-14 06:47:58,808 |   INFO   | user_metadata] Getting metadata for 0x42dddba609589322e5c6133939ddd20941f9abb2
[2022-03-14 06:48:01,838 |   INFO   | user_metadata] Getting metadata for 0x721931508df2764fd4f70c53da646cb8aed16ace
[2022-03-14 06:48:06,434 |   INFO   | user_metadata] Getting metadata for 0x6b4df334368b09f87b3722449703060eef284126
[2022-03-14 06:48:07,051 |  ERROR   | user_metadata] Error getting metadata for 0x6b4df334368b09f87b3722449703060eef284126
Traceback (most recent call last):
  File "user_metadata.py", line 45, in get_metadata
    response = requests.get(url, headers=headers, proxies=proxies, timeout=10)
  File "/usr/lib/python3/dist-packages/requests/api.py", line 75, in get
    return request('get', url, params=params, **kwargs)
  File "/usr/lib/python3/dist-packages/requests/api.py", line 60, in request
    return session.request(method=method, url=url, **kwargs)
  File "/usr/lib/python3/dist-packages/requests/sessions.py", line 533, in request
    resp = self.send(prep, **send_kwargs)
  File "/usr/lib/python3/dist-packages/requests/sessions.py", line 646, in send
    r = adapter.send(request, **kwargs)
  File "/usr/lib/python3/dist-packages/requests/adapters.py", line 439, in send
    resp = conn.urlopen(
  File "/usr/lib/python3/dist-packages/urllib3/connectionpool.py", line 665, in urlopen
    httplib_response = self._make_request(
  File "/usr/lib/python3/dist-packages/urllib3/connectionpool.py", line 421, in _make_request
    six.raise_from(e, None)
  File "<string>", line 3, in raise_from
  File "/usr/lib/python3/dist-packages/urllib3/connectionpool.py", line 416, in _make_request
    httplib_response = conn.getresponse()
  File "/usr/lib/python3.8/http/client.py", line 1348, in getresponse
    response.begin()
  File "/usr/lib/python3.8/http/client.py", line 316, in begin
    version, status, reason = self._read_status()
  File "/usr/lib/python3.8/http/client.py", line 277, in _read_status
    line = str(self.fp.readline(_MAXLINE + 1), "iso-8859-1")
  File "/usr/lib/python3.8/socket.py", line 669, in readinto
    return self._sock.recv_into(b)
  File "/usr/lib/python3/dist-packages/urllib3/contrib/pyopenssl.py", line 325, in recv_into
    if not util.wait_for_read(self.socket, self.socket.gettimeout()):
  File "/usr/lib/python3/dist-packages/urllib3/util/wait.py", line 146, in wait_for_read
    return wait_for_socket(sock, read=True, timeout=timeout)
  File "/usr/lib/python3/dist-packages/urllib3/util/wait.py", line 107, in poll_wait_for_socket
    return bool(_retry_on_intr(do_poll, timeout))
  File "/usr/lib/python3/dist-packages/urllib3/util/wait.py", line 43, in _retry_on_intr
    return fn(timeout)
  File "/usr/lib/python3/dist-packages/urllib3/util/wait.py", line 105, in do_poll
    return poll_obj.poll(t)
KeyboardInterrupt
[2022-03-14 06:48:08,501 | CRITICAL | user_metadata] Fatal error
Traceback (most recent call last):
  File "user_metadata.py", line 45, in get_metadata
    response = requests.get(url, headers=headers, proxies=proxies, timeout=10)
  File "/usr/lib/python3/dist-packages/requests/api.py", line 75, in get
    return request('get', url, params=params, **kwargs)
  File "/usr/lib/python3/dist-packages/requests/api.py", line 60, in request
    return session.request(method=method, url=url, **kwargs)
  File "/usr/lib/python3/dist-packages/requests/sessions.py", line 533, in request
    resp = self.send(prep, **send_kwargs)
  File "/usr/lib/python3/dist-packages/requests/sessions.py", line 646, in send
    r = adapter.send(request, **kwargs)
  File "/usr/lib/python3/dist-packages/requests/adapters.py", line 439, in send
    resp = conn.urlopen(
  File "/usr/lib/python3/dist-packages/urllib3/connectionpool.py", line 665, in urlopen
    httplib_response = self._make_request(
  File "/usr/lib/python3/dist-packages/urllib3/connectionpool.py", line 421, in _make_request
    six.raise_from(e, None)
  File "<string>", line 3, in raise_from
  File "/usr/lib/python3/dist-packages/urllib3/connectionpool.py", line 416, in _make_request
    httplib_response = conn.getresponse()
  File "/usr/lib/python3.8/http/client.py", line 1348, in getresponse
    response.begin()
  File "/usr/lib/python3.8/http/client.py", line 316, in begin
    version, status, reason = self._read_status()
  File "/usr/lib/python3.8/http/client.py", line 277, in _read_status
    line = str(self.fp.readline(_MAXLINE + 1), "iso-8859-1")
  File "/usr/lib/python3.8/socket.py", line 669, in readinto
    return self._sock.recv_into(b)
  File "/usr/lib/python3/dist-packages/urllib3/contrib/pyopenssl.py", line 325, in recv_into
    if not util.wait_for_read(self.socket, self.socket.gettimeout()):
  File "/usr/lib/python3/dist-packages/urllib3/util/wait.py", line 146, in wait_for_read
    return wait_for_socket(sock, read=True, timeout=timeout)
  File "/usr/lib/python3/dist-packages/urllib3/util/wait.py", line 107, in poll_wait_for_socket
    return bool(_retry_on_intr(do_poll, timeout))
  File "/usr/lib/python3/dist-packages/urllib3/util/wait.py", line 43, in _retry_on_intr
    return fn(timeout)
  File "/usr/lib/python3/dist-packages/urllib3/util/wait.py", line 105, in do_poll
    return poll_obj.poll(t)
KeyboardInterrupt

During handling of the above exception, another exception occurred:

Traceback (most recent call last):
  File "user_metadata.py", line 103, in <module>
    main()
  File "user_metadata.py", line 95, in main
    metadata = get_metadata(username)
  File "user_metadata.py", line 68, in get_metadata
    sleep(10)
KeyboardInterrupt
[2022-03-14 07:22:37,265 |   INFO   | user_metadata] Starting
[2022-03-14 07:22:37,266 |   INFO   | user_metadata] Loaded 1498 usernames
[2022-03-14 07:22:37,266 |   INFO   | user_metadata] Getting metadata for 0x482914ce89836db864987707ac8d96e965419efc
[2022-03-14 07:22:42,794 |   INFO   | user_metadata] Getting metadata for 0xe7079eec020ddfc3f1c0abe1d946c55e6ed30eb3
[2022-03-14 07:22:49,404 |   INFO   | user_metadata] Getting metadata for 0x8bbc693d042cea740e4ff01d7e0efb36110c36bf
[2022-03-14 07:22:54,544 |   INFO   | user_metadata] Getting metadata for 0xc3f733ca98e0dad0386979eb96fb1722a1a05e69
[2022-03-14 07:22:59,927 |   INFO   | user_metadata] Getting metadata for 0x29ebde3010cb23bac83b3cc4dd059a78317305fe
[2022-03-14 07:23:03,947 |   INFO   | user_metadata] Getting metadata for 0x97916e27632ec5f1f4c549ba7bf4c8850344a32b
[2022-03-14 07:23:09,933 |   INFO   | user_metadata] Getting metadata for 0xf8c75c5e9ec6875c57c0dbc30b59934b37908c4e
[2022-03-14 07:23:15,245 |   INFO   | user_metadata] Getting metadata for 0x69b47e91e2eea2525770ed93f6115b9d8f4fa132
[2022-03-14 07:23:19,665 |   INFO   | user_metadata] Getting metadata for 0xabeffb353dae4a177057e9a3e4a663386cf54758
[2022-03-14 07:23:24,256 |   INFO   | user_metadata] Getting metadata for 0x50dd57f50a17d57304e7a4f262da30beb31c2e87
[2022-03-14 07:23:30,218 |   INFO   | user_metadata] Getting metadata for 0x54be3a794282c030b15e43ae2bb182e14c409c5e
[2022-03-14 07:23:42,413 |   INFO   | user_metadata] Getting metadata for 0x08797952462b82db639ddbfdef2ab1718ffa7676
[2022-03-14 07:23:49,818 |   INFO   | user_metadata] Getting metadata for 0x2de14db256db2597fe3c8eed46ef5b20ba390823
[2022-03-14 07:23:57,546 |   INFO   | user_metadata] Getting metadata for 0x8bc1e2e9cf5dab703f8252473cbbdaef83843f95
[2022-03-14 07:24:04,348 |   INFO   | user_metadata] Getting metadata for 0x9af756e7be065dca83674ec17f3703579a544da1
[2022-03-14 07:24:12,926 |  ERROR   | user_metadata] Error getting metadata for 0x9af756e7be065dca83674ec17f3703579a544da1
Traceback (most recent call last):
  File "/usr/lib/python3/dist-packages/urllib3/contrib/pyopenssl.py", line 313, in recv_into
    return self.connection.recv_into(*args, **kwargs)
  File "/usr/lib/python3/dist-packages/OpenSSL/SSL.py", line 1822, in recv_into
    self._raise_ssl_error(self._ssl, result)
  File "/usr/lib/python3/dist-packages/OpenSSL/SSL.py", line 1622, in _raise_ssl_error
    raise WantReadError()
OpenSSL.SSL.WantReadError

During handling of the above exception, another exception occurred:

Traceback (most recent call last):
  File "user_metadata.py", line 45, in get_metadata
    response = requests.get(url, headers=headers, proxies=proxies, timeout=10)
  File "/usr/lib/python3/dist-packages/requests/api.py", line 75, in get
    return request('get', url, params=params, **kwargs)
  File "/usr/lib/python3/dist-packages/requests/api.py", line 60, in request
    return session.request(method=method, url=url, **kwargs)
  File "/usr/lib/python3/dist-packages/requests/sessions.py", line 533, in request
    resp = self.send(prep, **send_kwargs)
  File "/usr/lib/python3/dist-packages/requests/sessions.py", line 668, in send
    history = [resp for resp in gen] if allow_redirects else []
  File "/usr/lib/python3/dist-packages/requests/sessions.py", line 668, in <listcomp>
    history = [resp for resp in gen] if allow_redirects else []
  File "/usr/lib/python3/dist-packages/requests/sessions.py", line 239, in resolve_redirects
    resp = self.send(
  File "/usr/lib/python3/dist-packages/requests/sessions.py", line 686, in send
    r.content
  File "/usr/lib/python3/dist-packages/requests/models.py", line 828, in content
    self._content = b''.join(self.iter_content(CONTENT_CHUNK_SIZE)) or b''
  File "/usr/lib/python3/dist-packages/requests/models.py", line 750, in generate
    for chunk in self.raw.stream(chunk_size, decode_content=True):
  File "/usr/lib/python3/dist-packages/urllib3/response.py", line 560, in stream
    for line in self.read_chunked(amt, decode_content=decode_content):
  File "/usr/lib/python3/dist-packages/urllib3/response.py", line 755, in read_chunked
    chunk = self._handle_chunk(amt)
  File "/usr/lib/python3/dist-packages/urllib3/response.py", line 708, in _handle_chunk
    returned_chunk = self._fp._safe_read(self.chunk_left)
  File "/usr/lib/python3.8/http/client.py", line 613, in _safe_read
    data = self.fp.read(amt)
  File "/usr/lib/python3.8/socket.py", line 669, in readinto
    return self._sock.recv_into(b)
  File "/usr/lib/python3/dist-packages/urllib3/contrib/pyopenssl.py", line 325, in recv_into
    if not util.wait_for_read(self.socket, self.socket.gettimeout()):
  File "/usr/lib/python3/dist-packages/urllib3/util/wait.py", line 146, in wait_for_read
    return wait_for_socket(sock, read=True, timeout=timeout)
  File "/usr/lib/python3/dist-packages/urllib3/util/wait.py", line 107, in poll_wait_for_socket
    return bool(_retry_on_intr(do_poll, timeout))
  File "/usr/lib/python3/dist-packages/urllib3/util/wait.py", line 43, in _retry_on_intr
    return fn(timeout)
  File "/usr/lib/python3/dist-packages/urllib3/util/wait.py", line 105, in do_poll
    return poll_obj.poll(t)
KeyboardInterrupt
[2022-03-14 07:24:13,809 | CRITICAL | user_metadata] Fatal error
Traceback (most recent call last):
  File "/usr/lib/python3/dist-packages/urllib3/contrib/pyopenssl.py", line 313, in recv_into
    return self.connection.recv_into(*args, **kwargs)
  File "/usr/lib/python3/dist-packages/OpenSSL/SSL.py", line 1822, in recv_into
    self._raise_ssl_error(self._ssl, result)
  File "/usr/lib/python3/dist-packages/OpenSSL/SSL.py", line 1622, in _raise_ssl_error
    raise WantReadError()
OpenSSL.SSL.WantReadError

During handling of the above exception, another exception occurred:

Traceback (most recent call last):
  File "user_metadata.py", line 45, in get_metadata
    response = requests.get(url, headers=headers, proxies=proxies, timeout=10)
  File "/usr/lib/python3/dist-packages/requests/api.py", line 75, in get
    return request('get', url, params=params, **kwargs)
  File "/usr/lib/python3/dist-packages/requests/api.py", line 60, in request
    return session.request(method=method, url=url, **kwargs)
  File "/usr/lib/python3/dist-packages/requests/sessions.py", line 533, in request
    resp = self.send(prep, **send_kwargs)
  File "/usr/lib/python3/dist-packages/requests/sessions.py", line 668, in send
    history = [resp for resp in gen] if allow_redirects else []
  File "/usr/lib/python3/dist-packages/requests/sessions.py", line 668, in <listcomp>
    history = [resp for resp in gen] if allow_redirects else []
  File "/usr/lib/python3/dist-packages/requests/sessions.py", line 239, in resolve_redirects
    resp = self.send(
  File "/usr/lib/python3/dist-packages/requests/sessions.py", line 686, in send
    r.content
  File "/usr/lib/python3/dist-packages/requests/models.py", line 828, in content
    self._content = b''.join(self.iter_content(CONTENT_CHUNK_SIZE)) or b''
  File "/usr/lib/python3/dist-packages/requests/models.py", line 750, in generate
    for chunk in self.raw.stream(chunk_size, decode_content=True):
  File "/usr/lib/python3/dist-packages/urllib3/response.py", line 560, in stream
    for line in self.read_chunked(amt, decode_content=decode_content):
  File "/usr/lib/python3/dist-packages/urllib3/response.py", line 755, in read_chunked
    chunk = self._handle_chunk(amt)
  File "/usr/lib/python3/dist-packages/urllib3/response.py", line 708, in _handle_chunk
    returned_chunk = self._fp._safe_read(self.chunk_left)
  File "/usr/lib/python3.8/http/client.py", line 613, in _safe_read
    data = self.fp.read(amt)
  File "/usr/lib/python3.8/socket.py", line 669, in readinto
    return self._sock.recv_into(b)
  File "/usr/lib/python3/dist-packages/urllib3/contrib/pyopenssl.py", line 325, in recv_into
    if not util.wait_for_read(self.socket, self.socket.gettimeout()):
  File "/usr/lib/python3/dist-packages/urllib3/util/wait.py", line 146, in wait_for_read
    return wait_for_socket(sock, read=True, timeout=timeout)
  File "/usr/lib/python3/dist-packages/urllib3/util/wait.py", line 107, in poll_wait_for_socket
    return bool(_retry_on_intr(do_poll, timeout))
  File "/usr/lib/python3/dist-packages/urllib3/util/wait.py", line 43, in _retry_on_intr
    return fn(timeout)
  File "/usr/lib/python3/dist-packages/urllib3/util/wait.py", line 105, in do_poll
    return poll_obj.poll(t)
KeyboardInterrupt

During handling of the above exception, another exception occurred:

Traceback (most recent call last):
  File "user_metadata.py", line 103, in <module>
    main()
  File "user_metadata.py", line 95, in main
    metadata = get_metadata(username)
  File "user_metadata.py", line 68, in get_metadata
    sleep(10)
KeyboardInterrupt
[2022-03-14 07:26:51,164 |   INFO   | user_metadata] Starting
[2022-03-14 07:26:51,165 |   INFO   | user_metadata] Loaded 1498 usernames
[2022-03-14 07:26:51,165 |   INFO   | user_metadata] Getting metadata for 0x482914ce89836db864987707ac8d96e965419efc
[2022-03-14 07:26:53,463 |   INFO   | user_metadata] Getting metadata for 0xe7079eec020ddfc3f1c0abe1d946c55e6ed30eb3
[2022-03-14 07:26:56,761 |   INFO   | user_metadata] Getting metadata for 0x8bbc693d042cea740e4ff01d7e0efb36110c36bf
[2022-03-14 07:26:58,842 |   INFO   | user_metadata] Getting metadata for 0xc3f733ca98e0dad0386979eb96fb1722a1a05e69
[2022-03-14 07:27:00,908 |   INFO   | user_metadata] Getting metadata for 0x29ebde3010cb23bac83b3cc4dd059a78317305fe
[2022-03-14 07:27:02,814 |   INFO   | user_metadata] Getting metadata for 0x97916e27632ec5f1f4c549ba7bf4c8850344a32b
[2022-03-14 07:27:05,706 |   INFO   | user_metadata] Getting metadata for 0xf8c75c5e9ec6875c57c0dbc30b59934b37908c4e
[2022-03-14 07:27:08,844 |   INFO   | user_metadata] Getting metadata for 0x69b47e91e2eea2525770ed93f6115b9d8f4fa132
[2022-03-14 07:27:10,857 |   INFO   | user_metadata] Getting metadata for 0xabeffb353dae4a177057e9a3e4a663386cf54758
[2022-03-14 07:27:14,537 |   INFO   | user_metadata] Getting metadata for 0x50dd57f50a17d57304e7a4f262da30beb31c2e87
[2022-03-14 07:27:18,283 |   INFO   | user_metadata] Getting metadata for 0x54be3a794282c030b15e43ae2bb182e14c409c5e
[2022-03-14 07:27:22,951 |   INFO   | user_metadata] Getting metadata for 0x08797952462b82db639ddbfdef2ab1718ffa7676
[2022-03-14 07:27:27,291 |   INFO   | user_metadata] Getting metadata for 0x2de14db256db2597fe3c8eed46ef5b20ba390823
[2022-03-14 07:27:29,617 |   INFO   | user_metadata] Getting metadata for 0x8bc1e2e9cf5dab703f8252473cbbdaef83843f95
[2022-03-14 07:27:32,330 |   INFO   | user_metadata] Getting metadata for 0x9af756e7be065dca83674ec17f3703579a544da1
[2022-03-14 07:27:35,219 |   INFO   | user_metadata] Getting metadata for 0x8c685c44facb8bf246fcb0e383cca4bd46634bf8
[2022-03-14 07:27:37,345 |   INFO   | user_metadata] Getting metadata for 0x9edf9b08406fa69a9dd5f73269f8a927b4f772d7
[2022-03-14 07:27:39,947 |   INFO   | user_metadata] Getting metadata for 0x7eb413211a9de1cd2fe8b8bb6055636c43f7d206
[2022-03-14 07:27:40,825 |   INFO   | user_metadata] Getting metadata for 0x58cd128282d652a6d14d93d68b416db414ee2962
[2022-03-14 07:27:42,647 |   INFO   | user_metadata] Getting metadata for 0xb5696e4057b9ba76616cecb5a537eaca7b3cdf54
[2022-03-14 07:27:45,304 |   INFO   | user_metadata] Getting metadata for 0xf7afb2d272bcb74f54b631d56982ee9f649acd70
[2022-03-14 07:27:47,639 |   INFO   | user_metadata] Getting metadata for 0x2206168cde2b3652e2488d9a1283531a4d200aea
[2022-03-14 07:27:50,229 |   INFO   | user_metadata] Getting metadata for 0xd9d1c2623fbb4377d9bf29075e610a9b8b4805b4
[2022-03-14 07:27:54,278 |   INFO   | user_metadata] Getting metadata for 0x5b20783f4baabd33bb53dd77c9b0459f5701e36a
[2022-03-14 07:27:56,962 |   INFO   | user_metadata] Getting metadata for 0x19ac63521615455415a716f5dcbb49d065ae8092
[2022-03-14 07:27:58,321 |  ERROR   | user_metadata] Error getting metadata for 0x19ac63521615455415a716f5dcbb49d065ae8092
Traceback (most recent call last):
  File "user_metadata.py", line 45, in get_metadata
    response = requests.get(url, headers=headers, proxies=proxies, timeout=10)
  File "/usr/lib/python3/dist-packages/requests/api.py", line 75, in get
    return request('get', url, params=params, **kwargs)
  File "/usr/lib/python3/dist-packages/requests/api.py", line 60, in request
    return session.request(method=method, url=url, **kwargs)
  File "/usr/lib/python3/dist-packages/requests/sessions.py", line 533, in request
    resp = self.send(prep, **send_kwargs)
  File "/usr/lib/python3/dist-packages/requests/sessions.py", line 668, in send
    history = [resp for resp in gen] if allow_redirects else []
  File "/usr/lib/python3/dist-packages/requests/sessions.py", line 668, in <listcomp>
    history = [resp for resp in gen] if allow_redirects else []
  File "/usr/lib/python3/dist-packages/requests/sessions.py", line 239, in resolve_redirects
    resp = self.send(
  File "/usr/lib/python3/dist-packages/requests/sessions.py", line 646, in send
    r = adapter.send(request, **kwargs)
  File "/usr/lib/python3/dist-packages/requests/adapters.py", line 439, in send
    resp = conn.urlopen(
  File "/usr/lib/python3/dist-packages/urllib3/connectionpool.py", line 665, in urlopen
    httplib_response = self._make_request(
  File "/usr/lib/python3/dist-packages/urllib3/connectionpool.py", line 421, in _make_request
    six.raise_from(e, None)
  File "<string>", line 3, in raise_from
  File "/usr/lib/python3/dist-packages/urllib3/connectionpool.py", line 416, in _make_request
    httplib_response = conn.getresponse()
  File "/usr/lib/python3.8/http/client.py", line 1348, in getresponse
    response.begin()
  File "/usr/lib/python3.8/http/client.py", line 316, in begin
    version, status, reason = self._read_status()
  File "/usr/lib/python3.8/http/client.py", line 277, in _read_status
    line = str(self.fp.readline(_MAXLINE + 1), "iso-8859-1")
  File "/usr/lib/python3.8/socket.py", line 669, in readinto
    return self._sock.recv_into(b)
  File "/usr/lib/python3/dist-packages/urllib3/contrib/pyopenssl.py", line 325, in recv_into
    if not util.wait_for_read(self.socket, self.socket.gettimeout()):
  File "/usr/lib/python3/dist-packages/urllib3/util/wait.py", line 146, in wait_for_read
    return wait_for_socket(sock, read=True, timeout=timeout)
  File "/usr/lib/python3/dist-packages/urllib3/util/wait.py", line 107, in poll_wait_for_socket
    return bool(_retry_on_intr(do_poll, timeout))
  File "/usr/lib/python3/dist-packages/urllib3/util/wait.py", line 43, in _retry_on_intr
    return fn(timeout)
  File "/usr/lib/python3/dist-packages/urllib3/util/wait.py", line 105, in do_poll
    return poll_obj.poll(t)
KeyboardInterrupt
[2022-03-14 07:27:58,957 | CRITICAL | user_metadata] Fatal error
Traceback (most recent call last):
  File "user_metadata.py", line 45, in get_metadata
    response = requests.get(url, headers=headers, proxies=proxies, timeout=10)
  File "/usr/lib/python3/dist-packages/requests/api.py", line 75, in get
    return request('get', url, params=params, **kwargs)
  File "/usr/lib/python3/dist-packages/requests/api.py", line 60, in request
    return session.request(method=method, url=url, **kwargs)
  File "/usr/lib/python3/dist-packages/requests/sessions.py", line 533, in request
    resp = self.send(prep, **send_kwargs)
  File "/usr/lib/python3/dist-packages/requests/sessions.py", line 668, in send
    history = [resp for resp in gen] if allow_redirects else []
  File "/usr/lib/python3/dist-packages/requests/sessions.py", line 668, in <listcomp>
    history = [resp for resp in gen] if allow_redirects else []
  File "/usr/lib/python3/dist-packages/requests/sessions.py", line 239, in resolve_redirects
    resp = self.send(
  File "/usr/lib/python3/dist-packages/requests/sessions.py", line 646, in send
    r = adapter.send(request, **kwargs)
  File "/usr/lib/python3/dist-packages/requests/adapters.py", line 439, in send
    resp = conn.urlopen(
  File "/usr/lib/python3/dist-packages/urllib3/connectionpool.py", line 665, in urlopen
    httplib_response = self._make_request(
  File "/usr/lib/python3/dist-packages/urllib3/connectionpool.py", line 421, in _make_request
    six.raise_from(e, None)
  File "<string>", line 3, in raise_from
  File "/usr/lib/python3/dist-packages/urllib3/connectionpool.py", line 416, in _make_request
    httplib_response = conn.getresponse()
  File "/usr/lib/python3.8/http/client.py", line 1348, in getresponse
    response.begin()
  File "/usr/lib/python3.8/http/client.py", line 316, in begin
    version, status, reason = self._read_status()
  File "/usr/lib/python3.8/http/client.py", line 277, in _read_status
    line = str(self.fp.readline(_MAXLINE + 1), "iso-8859-1")
  File "/usr/lib/python3.8/socket.py", line 669, in readinto
    return self._sock.recv_into(b)
  File "/usr/lib/python3/dist-packages/urllib3/contrib/pyopenssl.py", line 325, in recv_into
    if not util.wait_for_read(self.socket, self.socket.gettimeout()):
  File "/usr/lib/python3/dist-packages/urllib3/util/wait.py", line 146, in wait_for_read
    return wait_for_socket(sock, read=True, timeout=timeout)
  File "/usr/lib/python3/dist-packages/urllib3/util/wait.py", line 107, in poll_wait_for_socket
    return bool(_retry_on_intr(do_poll, timeout))
  File "/usr/lib/python3/dist-packages/urllib3/util/wait.py", line 43, in _retry_on_intr
    return fn(timeout)
  File "/usr/lib/python3/dist-packages/urllib3/util/wait.py", line 105, in do_poll
    return poll_obj.poll(t)
KeyboardInterrupt

During handling of the above exception, another exception occurred:

Traceback (most recent call last):
  File "user_metadata.py", line 103, in <module>
    main()
  File "user_metadata.py", line 95, in main
    metadata = get_metadata(username)
  File "user_metadata.py", line 68, in get_metadata
    sleep(10)
KeyboardInterrupt
[2022-03-14 07:29:45,395 |   INFO   | user_metadata] Starting
[2022-03-14 07:29:45,396 |   INFO   | user_metadata] Loaded 1498 usernames
[2022-03-14 07:29:45,396 |   INFO   | user_metadata] Getting metadata for 0x482914ce89836db864987707ac8d96e965419efc
[2022-03-14 07:29:47,139 |   INFO   | user_metadata] Getting metadata for 0xe7079eec020ddfc3f1c0abe1d946c55e6ed30eb3
[2022-03-14 07:29:50,887 |   INFO   | user_metadata] Getting metadata for 0x8bbc693d042cea740e4ff01d7e0efb36110c36bf
[2022-03-14 07:29:52,801 |   INFO   | user_metadata] Getting metadata for 0xc3f733ca98e0dad0386979eb96fb1722a1a05e69
[2022-03-14 07:29:54,749 |   INFO   | user_metadata] Getting metadata for 0x29ebde3010cb23bac83b3cc4dd059a78317305fe
[2022-03-14 07:29:57,079 |   INFO   | user_metadata] Getting metadata for 0x97916e27632ec5f1f4c549ba7bf4c8850344a32b
[2022-03-14 07:29:59,680 |   INFO   | user_metadata] Getting metadata for 0xf8c75c5e9ec6875c57c0dbc30b59934b37908c4e
[2022-03-14 07:30:03,500 |   INFO   | user_metadata] Getting metadata for 0x69b47e91e2eea2525770ed93f6115b9d8f4fa132
[2022-03-14 07:30:05,627 |   INFO   | user_metadata] Getting metadata for 0xabeffb353dae4a177057e9a3e4a663386cf54758
[2022-03-14 07:30:08,636 |   INFO   | user_metadata] Getting metadata for 0x50dd57f50a17d57304e7a4f262da30beb31c2e87
[2022-03-14 07:30:11,839 |   INFO   | user_metadata] Getting metadata for 0x54be3a794282c030b15e43ae2bb182e14c409c5e
[2022-03-14 07:30:15,552 |   INFO   | user_metadata] Getting metadata for 0x08797952462b82db639ddbfdef2ab1718ffa7676
[2022-03-14 07:30:19,997 |   INFO   | user_metadata] Getting metadata for 0x2de14db256db2597fe3c8eed46ef5b20ba390823
[2022-03-14 07:30:22,918 |   INFO   | user_metadata] Getting metadata for 0x8bc1e2e9cf5dab703f8252473cbbdaef83843f95
[2022-03-14 07:30:23,733 |  ERROR   | user_metadata] Error parsing metadata for 0x8bc1e2e9cf5dab703f8252473cbbdaef83843f95
Traceback (most recent call last):
  File "user_metadata.py", line 75, in get_metadata
    account = json_data["props"]["relayCache"][0][1]["json"]["data"]["account"]
KeyError: 'relayCache'
[2022-03-14 07:30:23,734 |   INFO   | user_metadata] Getting metadata for 0x9af756e7be065dca83674ec17f3703579a544da1
[2022-03-14 07:30:27,382 |   INFO   | user_metadata] Getting metadata for 0x8c685c44facb8bf246fcb0e383cca4bd46634bf8
[2022-03-14 07:30:29,057 |   INFO   | user_metadata] Getting metadata for 0x9edf9b08406fa69a9dd5f73269f8a927b4f772d7
[2022-03-14 07:30:31,748 |   INFO   | user_metadata] Getting metadata for 0x7eb413211a9de1cd2fe8b8bb6055636c43f7d206
[2022-03-14 07:30:34,876 |   INFO   | user_metadata] Getting metadata for 0x58cd128282d652a6d14d93d68b416db414ee2962
[2022-03-14 07:30:37,190 |   INFO   | user_metadata] Getting metadata for 0xb5696e4057b9ba76616cecb5a537eaca7b3cdf54
[2022-03-14 07:30:40,175 |   INFO   | user_metadata] Getting metadata for 0xf7afb2d272bcb74f54b631d56982ee9f649acd70
[2022-03-14 07:30:42,945 |   INFO   | user_metadata] Getting metadata for 0x2206168cde2b3652e2488d9a1283531a4d200aea
[2022-03-14 07:30:45,132 |   INFO   | user_metadata] Getting metadata for 0xd9d1c2623fbb4377d9bf29075e610a9b8b4805b4
[2022-03-14 07:30:49,871 |   INFO   | user_metadata] Getting metadata for 0x5b20783f4baabd33bb53dd77c9b0459f5701e36a
[2022-03-14 07:30:53,177 |   INFO   | user_metadata] Getting metadata for 0x19ac63521615455415a716f5dcbb49d065ae8092
[2022-03-14 07:30:56,112 |   INFO   | user_metadata] Getting metadata for 0x68b42e44079d1d0a4a037e8c6ecd62c48967e69f
[2022-03-14 07:30:59,875 |  ERROR   | user_metadata] Error getting metadata for 0x68b42e44079d1d0a4a037e8c6ecd62c48967e69f
Traceback (most recent call last):
  File "user_metadata.py", line 45, in get_metadata
    response = requests.get(url, headers=headers, proxies=proxies, timeout=10)
  File "/usr/lib/python3/dist-packages/requests/api.py", line 75, in get
    return request('get', url, params=params, **kwargs)
  File "/usr/lib/python3/dist-packages/requests/api.py", line 60, in request
    return session.request(method=method, url=url, **kwargs)
  File "/usr/lib/python3/dist-packages/requests/sessions.py", line 533, in request
    resp = self.send(prep, **send_kwargs)
  File "/usr/lib/python3/dist-packages/requests/sessions.py", line 668, in send
    history = [resp for resp in gen] if allow_redirects else []
  File "/usr/lib/python3/dist-packages/requests/sessions.py", line 668, in <listcomp>
    history = [resp for resp in gen] if allow_redirects else []
  File "/usr/lib/python3/dist-packages/requests/sessions.py", line 239, in resolve_redirects
    resp = self.send(
  File "/usr/lib/python3/dist-packages/requests/sessions.py", line 646, in send
    r = adapter.send(request, **kwargs)
  File "/usr/lib/python3/dist-packages/requests/adapters.py", line 439, in send
    resp = conn.urlopen(
  File "/usr/lib/python3/dist-packages/urllib3/connectionpool.py", line 665, in urlopen
    httplib_response = self._make_request(
  File "/usr/lib/python3/dist-packages/urllib3/connectionpool.py", line 421, in _make_request
    six.raise_from(e, None)
  File "<string>", line 3, in raise_from
  File "/usr/lib/python3/dist-packages/urllib3/connectionpool.py", line 416, in _make_request
    httplib_response = conn.getresponse()
  File "/usr/lib/python3.8/http/client.py", line 1348, in getresponse
    response.begin()
  File "/usr/lib/python3.8/http/client.py", line 316, in begin
    version, status, reason = self._read_status()
  File "/usr/lib/python3.8/http/client.py", line 277, in _read_status
    line = str(self.fp.readline(_MAXLINE + 1), "iso-8859-1")
  File "/usr/lib/python3.8/socket.py", line 669, in readinto
    return self._sock.recv_into(b)
  File "/usr/lib/python3/dist-packages/urllib3/contrib/pyopenssl.py", line 325, in recv_into
    if not util.wait_for_read(self.socket, self.socket.gettimeout()):
  File "/usr/lib/python3/dist-packages/urllib3/util/wait.py", line 146, in wait_for_read
    return wait_for_socket(sock, read=True, timeout=timeout)
  File "/usr/lib/python3/dist-packages/urllib3/util/wait.py", line 107, in poll_wait_for_socket
    return bool(_retry_on_intr(do_poll, timeout))
  File "/usr/lib/python3/dist-packages/urllib3/util/wait.py", line 43, in _retry_on_intr
    return fn(timeout)
  File "/usr/lib/python3/dist-packages/urllib3/util/wait.py", line 105, in do_poll
    return poll_obj.poll(t)
KeyboardInterrupt
[2022-03-14 07:31:01,145 | CRITICAL | user_metadata] Fatal error
Traceback (most recent call last):
  File "user_metadata.py", line 45, in get_metadata
    response = requests.get(url, headers=headers, proxies=proxies, timeout=10)
  File "/usr/lib/python3/dist-packages/requests/api.py", line 75, in get
    return request('get', url, params=params, **kwargs)
  File "/usr/lib/python3/dist-packages/requests/api.py", line 60, in request
    return session.request(method=method, url=url, **kwargs)
  File "/usr/lib/python3/dist-packages/requests/sessions.py", line 533, in request
    resp = self.send(prep, **send_kwargs)
  File "/usr/lib/python3/dist-packages/requests/sessions.py", line 668, in send
    history = [resp for resp in gen] if allow_redirects else []
  File "/usr/lib/python3/dist-packages/requests/sessions.py", line 668, in <listcomp>
    history = [resp for resp in gen] if allow_redirects else []
  File "/usr/lib/python3/dist-packages/requests/sessions.py", line 239, in resolve_redirects
    resp = self.send(
  File "/usr/lib/python3/dist-packages/requests/sessions.py", line 646, in send
    r = adapter.send(request, **kwargs)
  File "/usr/lib/python3/dist-packages/requests/adapters.py", line 439, in send
    resp = conn.urlopen(
  File "/usr/lib/python3/dist-packages/urllib3/connectionpool.py", line 665, in urlopen
    httplib_response = self._make_request(
  File "/usr/lib/python3/dist-packages/urllib3/connectionpool.py", line 421, in _make_request
    six.raise_from(e, None)
  File "<string>", line 3, in raise_from
  File "/usr/lib/python3/dist-packages/urllib3/connectionpool.py", line 416, in _make_request
    httplib_response = conn.getresponse()
  File "/usr/lib/python3.8/http/client.py", line 1348, in getresponse
    response.begin()
  File "/usr/lib/python3.8/http/client.py", line 316, in begin
    version, status, reason = self._read_status()
  File "/usr/lib/python3.8/http/client.py", line 277, in _read_status
    line = str(self.fp.readline(_MAXLINE + 1), "iso-8859-1")
  File "/usr/lib/python3.8/socket.py", line 669, in readinto
    return self._sock.recv_into(b)
  File "/usr/lib/python3/dist-packages/urllib3/contrib/pyopenssl.py", line 325, in recv_into
    if not util.wait_for_read(self.socket, self.socket.gettimeout()):
  File "/usr/lib/python3/dist-packages/urllib3/util/wait.py", line 146, in wait_for_read
    return wait_for_socket(sock, read=True, timeout=timeout)
  File "/usr/lib/python3/dist-packages/urllib3/util/wait.py", line 107, in poll_wait_for_socket
    return bool(_retry_on_intr(do_poll, timeout))
  File "/usr/lib/python3/dist-packages/urllib3/util/wait.py", line 43, in _retry_on_intr
    return fn(timeout)
  File "/usr/lib/python3/dist-packages/urllib3/util/wait.py", line 105, in do_poll
    return poll_obj.poll(t)
KeyboardInterrupt

During handling of the above exception, another exception occurred:

Traceback (most recent call last):
  File "user_metadata.py", line 103, in <module>
    main()
  File "user_metadata.py", line 95, in main
    metadata = get_metadata(username)
  File "user_metadata.py", line 68, in get_metadata
    sleep(10)
KeyboardInterrupt
[2022-03-14 07:34:40,882 |   INFO   | user_metadata] Starting
[2022-03-14 07:34:40,883 |   INFO   | user_metadata] Loaded 1498 usernames
[2022-03-14 07:34:40,883 |   INFO   | user_metadata] Getting metadata for 0x482914ce89836db864987707ac8d96e965419efc
[2022-03-14 07:34:42,885 |  ERROR   | user_metadata] Error getting metadata for 0x482914ce89836db864987707ac8d96e965419efc
Traceback (most recent call last):
  File "user_metadata.py", line 45, in get_metadata
    response = requests.get(url, headers=headers, proxies=proxies, timeout=10)
  File "/usr/lib/python3/dist-packages/requests/api.py", line 75, in get
    return request('get', url, params=params, **kwargs)
  File "/usr/lib/python3/dist-packages/requests/api.py", line 60, in request
    return session.request(method=method, url=url, **kwargs)
  File "/usr/lib/python3/dist-packages/requests/sessions.py", line 533, in request
    resp = self.send(prep, **send_kwargs)
  File "/usr/lib/python3/dist-packages/requests/sessions.py", line 646, in send
    r = adapter.send(request, **kwargs)
  File "/usr/lib/python3/dist-packages/requests/adapters.py", line 439, in send
    resp = conn.urlopen(
  File "/usr/lib/python3/dist-packages/urllib3/connectionpool.py", line 665, in urlopen
    httplib_response = self._make_request(
  File "/usr/lib/python3/dist-packages/urllib3/connectionpool.py", line 421, in _make_request
    six.raise_from(e, None)
  File "<string>", line 3, in raise_from
  File "/usr/lib/python3/dist-packages/urllib3/connectionpool.py", line 416, in _make_request
    httplib_response = conn.getresponse()
  File "/usr/lib/python3.8/http/client.py", line 1348, in getresponse
    response.begin()
  File "/usr/lib/python3.8/http/client.py", line 316, in begin
    version, status, reason = self._read_status()
  File "/usr/lib/python3.8/http/client.py", line 277, in _read_status
    line = str(self.fp.readline(_MAXLINE + 1), "iso-8859-1")
  File "/usr/lib/python3.8/socket.py", line 669, in readinto
    return self._sock.recv_into(b)
  File "/usr/lib/python3/dist-packages/urllib3/contrib/pyopenssl.py", line 325, in recv_into
    if not util.wait_for_read(self.socket, self.socket.gettimeout()):
  File "/usr/lib/python3/dist-packages/urllib3/util/wait.py", line 146, in wait_for_read
    return wait_for_socket(sock, read=True, timeout=timeout)
  File "/usr/lib/python3/dist-packages/urllib3/util/wait.py", line 107, in poll_wait_for_socket
    return bool(_retry_on_intr(do_poll, timeout))
  File "/usr/lib/python3/dist-packages/urllib3/util/wait.py", line 43, in _retry_on_intr
    return fn(timeout)
  File "/usr/lib/python3/dist-packages/urllib3/util/wait.py", line 105, in do_poll
    return poll_obj.poll(t)
KeyboardInterrupt
[2022-03-14 07:34:47,911 | CRITICAL | user_metadata] Fatal error
Traceback (most recent call last):
  File "user_metadata.py", line 45, in get_metadata
    response = requests.get(url, headers=headers, proxies=proxies, timeout=10)
  File "/usr/lib/python3/dist-packages/requests/api.py", line 75, in get
    return request('get', url, params=params, **kwargs)
  File "/usr/lib/python3/dist-packages/requests/api.py", line 60, in request
    return session.request(method=method, url=url, **kwargs)
  File "/usr/lib/python3/dist-packages/requests/sessions.py", line 533, in request
    resp = self.send(prep, **send_kwargs)
  File "/usr/lib/python3/dist-packages/requests/sessions.py", line 646, in send
    r = adapter.send(request, **kwargs)
  File "/usr/lib/python3/dist-packages/requests/adapters.py", line 439, in send
    resp = conn.urlopen(
  File "/usr/lib/python3/dist-packages/urllib3/connectionpool.py", line 665, in urlopen
    httplib_response = self._make_request(
  File "/usr/lib/python3/dist-packages/urllib3/connectionpool.py", line 421, in _make_request
    six.raise_from(e, None)
  File "<string>", line 3, in raise_from
  File "/usr/lib/python3/dist-packages/urllib3/connectionpool.py", line 416, in _make_request
    httplib_response = conn.getresponse()
  File "/usr/lib/python3.8/http/client.py", line 1348, in getresponse
    response.begin()
  File "/usr/lib/python3.8/http/client.py", line 316, in begin
    version, status, reason = self._read_status()
  File "/usr/lib/python3.8/http/client.py", line 277, in _read_status
    line = str(self.fp.readline(_MAXLINE + 1), "iso-8859-1")
  File "/usr/lib/python3.8/socket.py", line 669, in readinto
    return self._sock.recv_into(b)
  File "/usr/lib/python3/dist-packages/urllib3/contrib/pyopenssl.py", line 325, in recv_into
    if not util.wait_for_read(self.socket, self.socket.gettimeout()):
  File "/usr/lib/python3/dist-packages/urllib3/util/wait.py", line 146, in wait_for_read
    return wait_for_socket(sock, read=True, timeout=timeout)
  File "/usr/lib/python3/dist-packages/urllib3/util/wait.py", line 107, in poll_wait_for_socket
    return bool(_retry_on_intr(do_poll, timeout))
  File "/usr/lib/python3/dist-packages/urllib3/util/wait.py", line 43, in _retry_on_intr
    return fn(timeout)
  File "/usr/lib/python3/dist-packages/urllib3/util/wait.py", line 105, in do_poll
    return poll_obj.poll(t)
KeyboardInterrupt

During handling of the above exception, another exception occurred:

Traceback (most recent call last):
  File "user_metadata.py", line 103, in <module>
    main()
  File "user_metadata.py", line 95, in main
    metadata = get_metadata(username)
  File "user_metadata.py", line 68, in get_metadata
    sleep(10)
KeyboardInterrupt
[2022-03-14 07:56:13,469 |   INFO   | user_metadata] Starting
[2022-03-14 07:56:13,485 |   INFO   | user_metadata] Loaded 1498 usernames
[2022-03-14 07:56:13,485 |   INFO   | user_metadata] Getting metadata for 0x482914ce89836db864987707ac8d96e965419efc
[2022-03-14 07:56:14,516 |   INFO   | user_metadata] Getting metadata for 0xe7079eec020ddfc3f1c0abe1d946c55e6ed30eb3
[2022-03-14 07:56:18,435 |   INFO   | user_metadata] Getting metadata for 0x8bbc693d042cea740e4ff01d7e0efb36110c36bf
[2022-03-14 07:56:20,874 |   INFO   | user_metadata] Getting metadata for 0xc3f733ca98e0dad0386979eb96fb1722a1a05e69
[2022-03-14 07:56:22,777 |   INFO   | user_metadata] Getting metadata for 0x29ebde3010cb23bac83b3cc4dd059a78317305fe
[2022-03-14 07:56:25,459 |   INFO   | user_metadata] Getting metadata for 0x97916e27632ec5f1f4c549ba7bf4c8850344a32b
[2022-03-14 07:56:28,842 |   INFO   | user_metadata] Getting metadata for 0xf8c75c5e9ec6875c57c0dbc30b59934b37908c4e
[2022-03-14 07:56:32,340 |   INFO   | user_metadata] Getting metadata for 0x69b47e91e2eea2525770ed93f6115b9d8f4fa132
[2022-03-14 07:56:34,782 |   INFO   | user_metadata] Getting metadata for 0xabeffb353dae4a177057e9a3e4a663386cf54758
[2022-03-14 07:56:38,747 |   INFO   | user_metadata] Getting metadata for 0x50dd57f50a17d57304e7a4f262da30beb31c2e87
[2022-03-14 07:56:42,082 |   INFO   | user_metadata] Getting metadata for 0x54be3a794282c030b15e43ae2bb182e14c409c5e
[2022-03-14 07:56:48,565 |   INFO   | user_metadata] Getting metadata for 0x08797952462b82db639ddbfdef2ab1718ffa7676
[2022-03-14 07:56:53,890 |   INFO   | user_metadata] Getting metadata for 0x2de14db256db2597fe3c8eed46ef5b20ba390823
[2022-03-14 07:56:55,617 |  ERROR   | user_metadata] Error getting metadata for 0x2de14db256db2597fe3c8eed46ef5b20ba390823
Traceback (most recent call last):
  File "user_metadata.py", line 45, in get_metadata
    response = requests.get(url, headers=headers, proxies=proxies, timeout=10)
  File "/home/martin/.local/lib/python3.8/site-packages/requests/api.py", line 75, in get
    return request('get', url, params=params, **kwargs)
  File "/home/martin/.local/lib/python3.8/site-packages/requests/api.py", line 61, in request
    return session.request(method=method, url=url, **kwargs)
  File "/home/martin/.local/lib/python3.8/site-packages/requests/sessions.py", line 529, in request
    resp = self.send(prep, **send_kwargs)
  File "/home/martin/.local/lib/python3.8/site-packages/requests/sessions.py", line 667, in send
    history = [resp for resp in gen]
  File "/home/martin/.local/lib/python3.8/site-packages/requests/sessions.py", line 667, in <listcomp>
    history = [resp for resp in gen]
  File "/home/martin/.local/lib/python3.8/site-packages/requests/sessions.py", line 237, in resolve_redirects
    resp = self.send(
  File "/home/martin/.local/lib/python3.8/site-packages/requests/sessions.py", line 645, in send
    r = adapter.send(request, **kwargs)
  File "/home/martin/.local/lib/python3.8/site-packages/requests/adapters.py", line 440, in send
    resp = conn.urlopen(
  File "/usr/lib/python3/dist-packages/urllib3/connectionpool.py", line 665, in urlopen
    httplib_response = self._make_request(
  File "/usr/lib/python3/dist-packages/urllib3/connectionpool.py", line 421, in _make_request
    six.raise_from(e, None)
  File "<string>", line 3, in raise_from
  File "/usr/lib/python3/dist-packages/urllib3/connectionpool.py", line 416, in _make_request
    httplib_response = conn.getresponse()
  File "/usr/lib/python3.8/http/client.py", line 1348, in getresponse
    response.begin()
  File "/usr/lib/python3.8/http/client.py", line 316, in begin
    version, status, reason = self._read_status()
  File "/usr/lib/python3.8/http/client.py", line 277, in _read_status
    line = str(self.fp.readline(_MAXLINE + 1), "iso-8859-1")
  File "/usr/lib/python3.8/socket.py", line 669, in readinto
    return self._sock.recv_into(b)
  File "/usr/lib/python3.8/ssl.py", line 1241, in recv_into
    return self.read(nbytes, buffer)
  File "/usr/lib/python3.8/ssl.py", line 1099, in read
    return self._sslobj.read(len, buffer)
KeyboardInterrupt
[2022-03-14 07:56:55,889 | CRITICAL | user_metadata] Fatal error
Traceback (most recent call last):
  File "user_metadata.py", line 45, in get_metadata
    response = requests.get(url, headers=headers, proxies=proxies, timeout=10)
  File "/home/martin/.local/lib/python3.8/site-packages/requests/api.py", line 75, in get
    return request('get', url, params=params, **kwargs)
  File "/home/martin/.local/lib/python3.8/site-packages/requests/api.py", line 61, in request
    return session.request(method=method, url=url, **kwargs)
  File "/home/martin/.local/lib/python3.8/site-packages/requests/sessions.py", line 529, in request
    resp = self.send(prep, **send_kwargs)
  File "/home/martin/.local/lib/python3.8/site-packages/requests/sessions.py", line 667, in send
    history = [resp for resp in gen]
  File "/home/martin/.local/lib/python3.8/site-packages/requests/sessions.py", line 667, in <listcomp>
    history = [resp for resp in gen]
  File "/home/martin/.local/lib/python3.8/site-packages/requests/sessions.py", line 237, in resolve_redirects
    resp = self.send(
  File "/home/martin/.local/lib/python3.8/site-packages/requests/sessions.py", line 645, in send
    r = adapter.send(request, **kwargs)
  File "/home/martin/.local/lib/python3.8/site-packages/requests/adapters.py", line 440, in send
    resp = conn.urlopen(
  File "/usr/lib/python3/dist-packages/urllib3/connectionpool.py", line 665, in urlopen
    httplib_response = self._make_request(
  File "/usr/lib/python3/dist-packages/urllib3/connectionpool.py", line 421, in _make_request
    six.raise_from(e, None)
  File "<string>", line 3, in raise_from
  File "/usr/lib/python3/dist-packages/urllib3/connectionpool.py", line 416, in _make_request
    httplib_response = conn.getresponse()
  File "/usr/lib/python3.8/http/client.py", line 1348, in getresponse
    response.begin()
  File "/usr/lib/python3.8/http/client.py", line 316, in begin
    version, status, reason = self._read_status()
  File "/usr/lib/python3.8/http/client.py", line 277, in _read_status
    line = str(self.fp.readline(_MAXLINE + 1), "iso-8859-1")
  File "/usr/lib/python3.8/socket.py", line 669, in readinto
    return self._sock.recv_into(b)
  File "/usr/lib/python3.8/ssl.py", line 1241, in recv_into
    return self.read(nbytes, buffer)
  File "/usr/lib/python3.8/ssl.py", line 1099, in read
    return self._sslobj.read(len, buffer)
KeyboardInterrupt

During handling of the above exception, another exception occurred:

Traceback (most recent call last):
  File "user_metadata.py", line 103, in <module>
    main()
  File "user_metadata.py", line 95, in main
    metadata = get_metadata(username)
  File "user_metadata.py", line 68, in get_metadata
    sleep(10)
KeyboardInterrupt
[2022-03-14 07:58:37,733 |   INFO   | user_metadata] Starting
[2022-03-14 07:58:37,734 |   INFO   | user_metadata] Loaded 1498 usernames
[2022-03-14 07:58:37,734 |   INFO   | user_metadata] Getting metadata for 0x482914ce89836db864987707ac8d96e965419efc
[2022-03-14 07:58:39,695 |   INFO   | user_metadata] Getting metadata for 0xe7079eec020ddfc3f1c0abe1d946c55e6ed30eb3
[2022-03-14 07:58:43,976 |   INFO   | user_metadata] Getting metadata for 0x8bbc693d042cea740e4ff01d7e0efb36110c36bf
[2022-03-14 07:58:47,106 |   INFO   | user_metadata] Getting metadata for 0xc3f733ca98e0dad0386979eb96fb1722a1a05e69
[2022-03-14 07:58:48,968 |   INFO   | user_metadata] Getting metadata for 0x29ebde3010cb23bac83b3cc4dd059a78317305fe
[2022-03-14 07:58:51,526 |   INFO   | user_metadata] Getting metadata for 0x97916e27632ec5f1f4c549ba7bf4c8850344a32b
[2022-03-14 07:58:54,703 |   INFO   | user_metadata] Getting metadata for 0xf8c75c5e9ec6875c57c0dbc30b59934b37908c4e
[2022-03-14 07:58:57,476 |   INFO   | user_metadata] Getting metadata for 0x69b47e91e2eea2525770ed93f6115b9d8f4fa132
[2022-03-14 07:58:59,903 |   INFO   | user_metadata] Getting metadata for 0xabeffb353dae4a177057e9a3e4a663386cf54758
[2022-03-14 07:59:03,529 |   INFO   | user_metadata] Getting metadata for 0x50dd57f50a17d57304e7a4f262da30beb31c2e87
[2022-03-14 07:59:06,878 |   INFO   | user_metadata] Getting metadata for 0x54be3a794282c030b15e43ae2bb182e14c409c5e
[2022-03-14 07:59:08,289 |  ERROR   | user_metadata] Error getting metadata for 0x54be3a794282c030b15e43ae2bb182e14c409c5e
Traceback (most recent call last):
  File "user_metadata.py", line 45, in get_metadata
    response = requests.get(url, headers=headers, proxies=proxies, timeout=10)
  File "/usr/lib/python3/dist-packages/requests/api.py", line 75, in get
    return request('get', url, params=params, **kwargs)
  File "/usr/lib/python3/dist-packages/requests/api.py", line 60, in request
    return session.request(method=method, url=url, **kwargs)
  File "/usr/lib/python3/dist-packages/requests/sessions.py", line 533, in request
    resp = self.send(prep, **send_kwargs)
  File "/usr/lib/python3/dist-packages/requests/sessions.py", line 668, in send
    history = [resp for resp in gen] if allow_redirects else []
  File "/usr/lib/python3/dist-packages/requests/sessions.py", line 668, in <listcomp>
    history = [resp for resp in gen] if allow_redirects else []
  File "/usr/lib/python3/dist-packages/requests/sessions.py", line 239, in resolve_redirects
    resp = self.send(
  File "/usr/lib/python3/dist-packages/requests/sessions.py", line 646, in send
    r = adapter.send(request, **kwargs)
  File "/usr/lib/python3/dist-packages/requests/adapters.py", line 439, in send
    resp = conn.urlopen(
  File "/usr/lib/python3/dist-packages/urllib3/connectionpool.py", line 665, in urlopen
    httplib_response = self._make_request(
  File "/usr/lib/python3/dist-packages/urllib3/connectionpool.py", line 421, in _make_request
    six.raise_from(e, None)
  File "<string>", line 3, in raise_from
  File "/usr/lib/python3/dist-packages/urllib3/connectionpool.py", line 416, in _make_request
    httplib_response = conn.getresponse()
  File "/usr/lib/python3.8/http/client.py", line 1348, in getresponse
    response.begin()
  File "/usr/lib/python3.8/http/client.py", line 316, in begin
    version, status, reason = self._read_status()
  File "/usr/lib/python3.8/http/client.py", line 277, in _read_status
    line = str(self.fp.readline(_MAXLINE + 1), "iso-8859-1")
  File "/usr/lib/python3.8/socket.py", line 669, in readinto
    return self._sock.recv_into(b)
  File "/usr/lib/python3/dist-packages/urllib3/contrib/pyopenssl.py", line 325, in recv_into
    if not util.wait_for_read(self.socket, self.socket.gettimeout()):
  File "/usr/lib/python3/dist-packages/urllib3/util/wait.py", line 146, in wait_for_read
    return wait_for_socket(sock, read=True, timeout=timeout)
  File "/usr/lib/python3/dist-packages/urllib3/util/wait.py", line 107, in poll_wait_for_socket
    return bool(_retry_on_intr(do_poll, timeout))
  File "/usr/lib/python3/dist-packages/urllib3/util/wait.py", line 43, in _retry_on_intr
    return fn(timeout)
  File "/usr/lib/python3/dist-packages/urllib3/util/wait.py", line 105, in do_poll
    return poll_obj.poll(t)
KeyboardInterrupt
[2022-03-14 07:59:08,436 | CRITICAL | user_metadata] Fatal error
Traceback (most recent call last):
  File "user_metadata.py", line 45, in get_metadata
    response = requests.get(url, headers=headers, proxies=proxies, timeout=10)
  File "/usr/lib/python3/dist-packages/requests/api.py", line 75, in get
    return request('get', url, params=params, **kwargs)
  File "/usr/lib/python3/dist-packages/requests/api.py", line 60, in request
    return session.request(method=method, url=url, **kwargs)
  File "/usr/lib/python3/dist-packages/requests/sessions.py", line 533, in request
    resp = self.send(prep, **send_kwargs)
  File "/usr/lib/python3/dist-packages/requests/sessions.py", line 668, in send
    history = [resp for resp in gen] if allow_redirects else []
  File "/usr/lib/python3/dist-packages/requests/sessions.py", line 668, in <listcomp>
    history = [resp for resp in gen] if allow_redirects else []
  File "/usr/lib/python3/dist-packages/requests/sessions.py", line 239, in resolve_redirects
    resp = self.send(
  File "/usr/lib/python3/dist-packages/requests/sessions.py", line 646, in send
    r = adapter.send(request, **kwargs)
  File "/usr/lib/python3/dist-packages/requests/adapters.py", line 439, in send
    resp = conn.urlopen(
  File "/usr/lib/python3/dist-packages/urllib3/connectionpool.py", line 665, in urlopen
    httplib_response = self._make_request(
  File "/usr/lib/python3/dist-packages/urllib3/connectionpool.py", line 421, in _make_request
    six.raise_from(e, None)
  File "<string>", line 3, in raise_from
  File "/usr/lib/python3/dist-packages/urllib3/connectionpool.py", line 416, in _make_request
    httplib_response = conn.getresponse()
  File "/usr/lib/python3.8/http/client.py", line 1348, in getresponse
    response.begin()
  File "/usr/lib/python3.8/http/client.py", line 316, in begin
    version, status, reason = self._read_status()
  File "/usr/lib/python3.8/http/client.py", line 277, in _read_status
    line = str(self.fp.readline(_MAXLINE + 1), "iso-8859-1")
  File "/usr/lib/python3.8/socket.py", line 669, in readinto
    return self._sock.recv_into(b)
  File "/usr/lib/python3/dist-packages/urllib3/contrib/pyopenssl.py", line 325, in recv_into
    if not util.wait_for_read(self.socket, self.socket.gettimeout()):
  File "/usr/lib/python3/dist-packages/urllib3/util/wait.py", line 146, in wait_for_read
    return wait_for_socket(sock, read=True, timeout=timeout)
  File "/usr/lib/python3/dist-packages/urllib3/util/wait.py", line 107, in poll_wait_for_socket
    return bool(_retry_on_intr(do_poll, timeout))
  File "/usr/lib/python3/dist-packages/urllib3/util/wait.py", line 43, in _retry_on_intr
    return fn(timeout)
  File "/usr/lib/python3/dist-packages/urllib3/util/wait.py", line 105, in do_poll
    return poll_obj.poll(t)
KeyboardInterrupt

During handling of the above exception, another exception occurred:

Traceback (most recent call last):
  File "user_metadata.py", line 103, in <module>
    main()
  File "user_metadata.py", line 95, in main
    metadata = get_metadata(username)
  File "user_metadata.py", line 68, in get_metadata
    sleep(10)
KeyboardInterrupt
[2022-03-14 07:59:21,509 |   INFO   | user_metadata] Starting
[2022-03-14 07:59:21,510 |   INFO   | user_metadata] Loaded 1498 usernames
[2022-03-14 07:59:21,510 |   INFO   | user_metadata] Getting metadata for 0x482914ce89836db864987707ac8d96e965419efc
[2022-03-14 07:59:24,084 |   INFO   | user_metadata] Getting metadata for 0xe7079eec020ddfc3f1c0abe1d946c55e6ed30eb3
[2022-03-14 07:59:27,305 |   INFO   | user_metadata] Getting metadata for 0x8bbc693d042cea740e4ff01d7e0efb36110c36bf
[2022-03-14 07:59:30,426 |   INFO   | user_metadata] Getting metadata for 0xc3f733ca98e0dad0386979eb96fb1722a1a05e69
[2022-03-14 07:59:32,383 |   INFO   | user_metadata] Getting metadata for 0x29ebde3010cb23bac83b3cc4dd059a78317305fe
[2022-03-14 07:59:34,859 |   INFO   | user_metadata] Getting metadata for 0x97916e27632ec5f1f4c549ba7bf4c8850344a32b
[2022-03-14 07:59:39,478 |   INFO   | user_metadata] Getting metadata for 0xf8c75c5e9ec6875c57c0dbc30b59934b37908c4e
[2022-03-14 07:59:44,113 |   INFO   | user_metadata] Getting metadata for 0x69b47e91e2eea2525770ed93f6115b9d8f4fa132
[2022-03-14 07:59:46,711 |   INFO   | user_metadata] Getting metadata for 0xabeffb353dae4a177057e9a3e4a663386cf54758
[2022-03-14 07:59:49,669 |   INFO   | user_metadata] Getting metadata for 0x50dd57f50a17d57304e7a4f262da30beb31c2e87
[2022-03-14 07:59:52,788 |   INFO   | user_metadata] Getting metadata for 0x54be3a794282c030b15e43ae2bb182e14c409c5e
[2022-03-14 07:59:56,621 |   INFO   | user_metadata] Getting metadata for 0x08797952462b82db639ddbfdef2ab1718ffa7676
[2022-03-14 08:00:01,784 |   INFO   | user_metadata] Getting metadata for 0x2de14db256db2597fe3c8eed46ef5b20ba390823
[2022-03-14 08:00:04,813 |   INFO   | user_metadata] Getting metadata for 0x8bc1e2e9cf5dab703f8252473cbbdaef83843f95
[2022-03-14 08:00:08,662 |   INFO   | user_metadata] Getting metadata for 0x9af756e7be065dca83674ec17f3703579a544da1
[2022-03-14 08:00:12,636 |   INFO   | user_metadata] Getting metadata for 0x8c685c44facb8bf246fcb0e383cca4bd46634bf8
[2022-03-14 08:00:15,369 |   INFO   | user_metadata] Getting metadata for 0x9edf9b08406fa69a9dd5f73269f8a927b4f772d7
[2022-03-14 08:00:18,304 |   INFO   | user_metadata] Getting metadata for 0x7eb413211a9de1cd2fe8b8bb6055636c43f7d206
[2022-03-14 08:00:23,112 |   INFO   | user_metadata] Getting metadata for 0x58cd128282d652a6d14d93d68b416db414ee2962
[2022-03-14 08:00:26,889 |   INFO   | user_metadata] Getting metadata for 0xb5696e4057b9ba76616cecb5a537eaca7b3cdf54
[2022-03-14 08:00:30,983 |   INFO   | user_metadata] Getting metadata for 0xf7afb2d272bcb74f54b631d56982ee9f649acd70
[2022-03-14 08:00:34,127 |   INFO   | user_metadata] Getting metadata for 0x2206168cde2b3652e2488d9a1283531a4d200aea
[2022-03-14 08:00:37,837 |   INFO   | user_metadata] Getting metadata for 0xd9d1c2623fbb4377d9bf29075e610a9b8b4805b4
[2022-03-14 08:00:44,323 |   INFO   | user_metadata] Getting metadata for 0x5b20783f4baabd33bb53dd77c9b0459f5701e36a
[2022-03-14 08:00:47,973 |   INFO   | user_metadata] Getting metadata for 0x19ac63521615455415a716f5dcbb49d065ae8092
[2022-03-14 08:00:52,270 |   INFO   | user_metadata] Getting metadata for 0x68b42e44079d1d0a4a037e8c6ecd62c48967e69f
[2022-03-14 08:00:56,966 |   INFO   | user_metadata] Getting metadata for 0x42dddba609589322e5c6133939ddd20941f9abb2
[2022-03-14 08:01:00,871 |   INFO   | user_metadata] Getting metadata for 0x721931508df2764fd4f70c53da646cb8aed16ace
[2022-03-14 08:01:01,310 |  ERROR   | user_metadata] Error getting metadata for 0x721931508df2764fd4f70c53da646cb8aed16ace
Traceback (most recent call last):
  File "/usr/lib/python3/dist-packages/urllib3/contrib/pyopenssl.py", line 485, in wrap_socket
    cnx.do_handshake()
  File "/usr/lib/python3/dist-packages/OpenSSL/SSL.py", line 1915, in do_handshake
    self._raise_ssl_error(self._ssl, result)
  File "/usr/lib/python3/dist-packages/OpenSSL/SSL.py", line 1622, in _raise_ssl_error
    raise WantReadError()
OpenSSL.SSL.WantReadError

During handling of the above exception, another exception occurred:

Traceback (most recent call last):
  File "user_metadata.py", line 45, in get_metadata
    response = requests.get(url, headers=headers, proxies=proxies, timeout=10)
  File "/usr/lib/python3/dist-packages/requests/api.py", line 75, in get
    return request('get', url, params=params, **kwargs)
  File "/usr/lib/python3/dist-packages/requests/api.py", line 60, in request
    return session.request(method=method, url=url, **kwargs)
  File "/usr/lib/python3/dist-packages/requests/sessions.py", line 533, in request
    resp = self.send(prep, **send_kwargs)
  File "/usr/lib/python3/dist-packages/requests/sessions.py", line 646, in send
    r = adapter.send(request, **kwargs)
  File "/usr/lib/python3/dist-packages/requests/adapters.py", line 439, in send
    resp = conn.urlopen(
  File "/usr/lib/python3/dist-packages/urllib3/connectionpool.py", line 662, in urlopen
    self._prepare_proxy(conn)
  File "/usr/lib/python3/dist-packages/urllib3/connectionpool.py", line 950, in _prepare_proxy
    conn.connect()
  File "/usr/lib/python3/dist-packages/urllib3/connection.py", line 366, in connect
    self.sock = ssl_wrap_socket(
  File "/usr/lib/python3/dist-packages/urllib3/util/ssl_.py", line 370, in ssl_wrap_socket
    return context.wrap_socket(sock, server_hostname=server_hostname)
  File "/usr/lib/python3/dist-packages/urllib3/contrib/pyopenssl.py", line 487, in wrap_socket
    if not util.wait_for_read(sock, sock.gettimeout()):
  File "/usr/lib/python3/dist-packages/urllib3/util/wait.py", line 146, in wait_for_read
    return wait_for_socket(sock, read=True, timeout=timeout)
  File "/usr/lib/python3/dist-packages/urllib3/util/wait.py", line 107, in poll_wait_for_socket
    return bool(_retry_on_intr(do_poll, timeout))
  File "/usr/lib/python3/dist-packages/urllib3/util/wait.py", line 43, in _retry_on_intr
    return fn(timeout)
  File "/usr/lib/python3/dist-packages/urllib3/util/wait.py", line 105, in do_poll
    return poll_obj.poll(t)
KeyboardInterrupt
[2022-03-14 08:01:02,328 | CRITICAL | user_metadata] Fatal error
Traceback (most recent call last):
  File "/usr/lib/python3/dist-packages/urllib3/contrib/pyopenssl.py", line 485, in wrap_socket
    cnx.do_handshake()
  File "/usr/lib/python3/dist-packages/OpenSSL/SSL.py", line 1915, in do_handshake
    self._raise_ssl_error(self._ssl, result)
  File "/usr/lib/python3/dist-packages/OpenSSL/SSL.py", line 1622, in _raise_ssl_error
    raise WantReadError()
OpenSSL.SSL.WantReadError

During handling of the above exception, another exception occurred:

Traceback (most recent call last):
  File "user_metadata.py", line 45, in get_metadata
    response = requests.get(url, headers=headers, proxies=proxies, timeout=10)
  File "/usr/lib/python3/dist-packages/requests/api.py", line 75, in get
    return request('get', url, params=params, **kwargs)
  File "/usr/lib/python3/dist-packages/requests/api.py", line 60, in request
    return session.request(method=method, url=url, **kwargs)
  File "/usr/lib/python3/dist-packages/requests/sessions.py", line 533, in request
    resp = self.send(prep, **send_kwargs)
  File "/usr/lib/python3/dist-packages/requests/sessions.py", line 646, in send
    r = adapter.send(request, **kwargs)
  File "/usr/lib/python3/dist-packages/requests/adapters.py", line 439, in send
    resp = conn.urlopen(
  File "/usr/lib/python3/dist-packages/urllib3/connectionpool.py", line 662, in urlopen
    self._prepare_proxy(conn)
  File "/usr/lib/python3/dist-packages/urllib3/connectionpool.py", line 950, in _prepare_proxy
    conn.connect()
  File "/usr/lib/python3/dist-packages/urllib3/connection.py", line 366, in connect
    self.sock = ssl_wrap_socket(
  File "/usr/lib/python3/dist-packages/urllib3/util/ssl_.py", line 370, in ssl_wrap_socket
    return context.wrap_socket(sock, server_hostname=server_hostname)
  File "/usr/lib/python3/dist-packages/urllib3/contrib/pyopenssl.py", line 487, in wrap_socket
    if not util.wait_for_read(sock, sock.gettimeout()):
  File "/usr/lib/python3/dist-packages/urllib3/util/wait.py", line 146, in wait_for_read
    return wait_for_socket(sock, read=True, timeout=timeout)
  File "/usr/lib/python3/dist-packages/urllib3/util/wait.py", line 107, in poll_wait_for_socket
    return bool(_retry_on_intr(do_poll, timeout))
  File "/usr/lib/python3/dist-packages/urllib3/util/wait.py", line 43, in _retry_on_intr
    return fn(timeout)
  File "/usr/lib/python3/dist-packages/urllib3/util/wait.py", line 105, in do_poll
    return poll_obj.poll(t)
KeyboardInterrupt

During handling of the above exception, another exception occurred:

Traceback (most recent call last):
  File "user_metadata.py", line 103, in <module>
    main()
  File "user_metadata.py", line 95, in main
    metadata = get_metadata(username)
  File "user_metadata.py", line 68, in get_metadata
    sleep(10)
KeyboardInterrupt
[2022-03-14 08:14:37,751 |   INFO   | user_metadata] Starting
[2022-03-14 08:14:37,767 |   INFO   | user_metadata] Loaded 1498 usernames
[2022-03-14 08:14:37,768 |   INFO   | user_metadata] Getting metadata for 0x482914ce89836db864987707ac8d96e965419efc
[2022-03-14 08:14:41,985 |   INFO   | user_metadata] Getting metadata for 0xe7079eec020ddfc3f1c0abe1d946c55e6ed30eb3
[2022-03-14 08:14:49,195 |   INFO   | user_metadata] Getting metadata for 0x8bbc693d042cea740e4ff01d7e0efb36110c36bf
[2022-03-14 08:14:54,800 |   INFO   | user_metadata] Getting metadata for 0xc3f733ca98e0dad0386979eb96fb1722a1a05e69
[2022-03-14 08:14:59,924 |   INFO   | user_metadata] Getting metadata for 0x29ebde3010cb23bac83b3cc4dd059a78317305fe
[2022-03-14 08:15:05,789 |   INFO   | user_metadata] Getting metadata for 0x97916e27632ec5f1f4c549ba7bf4c8850344a32b
[2022-03-14 08:15:11,760 |   INFO   | user_metadata] Getting metadata for 0xf8c75c5e9ec6875c57c0dbc30b59934b37908c4e
[2022-03-14 08:15:18,230 |   INFO   | user_metadata] Getting metadata for 0x69b47e91e2eea2525770ed93f6115b9d8f4fa132
[2022-03-14 08:15:23,682 |   INFO   | user_metadata] Getting metadata for 0xabeffb353dae4a177057e9a3e4a663386cf54758
[2022-03-14 08:15:28,886 |   INFO   | user_metadata] Getting metadata for 0x50dd57f50a17d57304e7a4f262da30beb31c2e87
[2022-03-14 08:15:35,324 |   INFO   | user_metadata] Getting metadata for 0x54be3a794282c030b15e43ae2bb182e14c409c5e
[2022-03-14 08:15:44,250 |   INFO   | user_metadata] Getting metadata for 0x08797952462b82db639ddbfdef2ab1718ffa7676
[2022-03-14 08:15:53,154 |   INFO   | user_metadata] Getting metadata for 0x2de14db256db2597fe3c8eed46ef5b20ba390823
[2022-03-14 08:16:00,887 |   INFO   | user_metadata] Getting metadata for 0x8bc1e2e9cf5dab703f8252473cbbdaef83843f95
[2022-03-14 08:16:05,888 |   INFO   | user_metadata] Getting metadata for 0x9af756e7be065dca83674ec17f3703579a544da1
[2022-03-14 08:16:14,466 |   INFO   | user_metadata] Getting metadata for 0x8c685c44facb8bf246fcb0e383cca4bd46634bf8
[2022-03-14 08:16:21,923 |   INFO   | user_metadata] Getting metadata for 0x9edf9b08406fa69a9dd5f73269f8a927b4f772d7
[2022-03-14 08:16:25,546 |   INFO   | user_metadata] Getting metadata for 0x7eb413211a9de1cd2fe8b8bb6055636c43f7d206
[2022-03-14 08:16:29,475 |   INFO   | user_metadata] Getting metadata for 0x58cd128282d652a6d14d93d68b416db414ee2962
[2022-03-14 08:16:32,533 |   INFO   | user_metadata] Getting metadata for 0xb5696e4057b9ba76616cecb5a537eaca7b3cdf54
[2022-03-14 08:16:36,071 |   INFO   | user_metadata] Getting metadata for 0xf7afb2d272bcb74f54b631d56982ee9f649acd70
[2022-03-14 08:16:38,807 |   INFO   | user_metadata] Getting metadata for 0x2206168cde2b3652e2488d9a1283531a4d200aea
[2022-03-14 08:16:41,473 |   INFO   | user_metadata] Getting metadata for 0xd9d1c2623fbb4377d9bf29075e610a9b8b4805b4
[2022-03-14 08:16:46,421 |   INFO   | user_metadata] Getting metadata for 0x5b20783f4baabd33bb53dd77c9b0459f5701e36a
[2022-03-14 08:16:49,780 |   INFO   | user_metadata] Getting metadata for 0x19ac63521615455415a716f5dcbb49d065ae8092
[2022-03-14 08:16:53,724 |   INFO   | user_metadata] Getting metadata for 0x68b42e44079d1d0a4a037e8c6ecd62c48967e69f
[2022-03-14 08:16:58,437 |   INFO   | user_metadata] Getting metadata for 0x42dddba609589322e5c6133939ddd20941f9abb2
[2022-03-14 08:17:02,049 |   INFO   | user_metadata] Getting metadata for 0x721931508df2764fd4f70c53da646cb8aed16ace
[2022-03-14 08:17:07,586 |   INFO   | user_metadata] Getting metadata for 0x6b4df334368b09f87b3722449703060eef284126
[2022-03-14 08:17:10,020 |   INFO   | user_metadata] Getting metadata for 0x4a90e18f3e90074a820532a3da62b347ea86711b
[2022-03-14 08:17:13,525 |   INFO   | user_metadata] Getting metadata for 0x81840dd9783fe5ac80978311d3d8e167c6a326a0
[2022-03-14 08:17:16,972 |   INFO   | user_metadata] Getting metadata for 0xc585d35fb8c9d136d6443a30fd88ccbb5f4cb86d
[2022-03-14 08:17:20,246 |   INFO   | user_metadata] Getting metadata for 0xe5193d2be4d4819f717092afc95e806f09a79964
[2022-03-14 08:17:24,050 |   INFO   | user_metadata] Getting metadata for 0xad097fdcd58535250c59807d6683e0a6b688d6cc
[2022-03-14 08:17:28,115 |   INFO   | user_metadata] Getting metadata for 0xd38a87d7b690323ef6883e887614502abcf9b1eb
[2022-03-14 08:17:31,156 |   INFO   | user_metadata] Getting metadata for 0x5a5617ba16beba3d04ae3c6b1e9d522c1856763c
[2022-03-14 08:17:35,327 |   INFO   | user_metadata] Getting metadata for 0xf696ab3e4f9d52482b8350ffae67d21fda78e601
[2022-03-14 08:17:38,744 |   INFO   | user_metadata] Getting metadata for 0xcc739b45da0123047cd0103b88f968b22ebdfc66
[2022-03-14 08:17:42,252 |   INFO   | user_metadata] Getting metadata for 0x4897d38b0974051d8fa34364e37a5993f4a966a5
[2022-03-14 08:17:45,725 |   INFO   | user_metadata] Getting metadata for 0x3abedba3052845ce3f57818032bfa747cded3fca
[2022-03-14 08:17:48,448 |   INFO   | user_metadata] Getting metadata for 0xdc080a3447ae4aa86de38f75d7b344fc4c0119c4
[2022-03-14 08:17:52,112 |   INFO   | user_metadata] Getting metadata for 0x762ec7ca4658e76002447b0a29e1f44f575dbebc
[2022-03-14 08:17:55,270 |   INFO   | user_metadata] Getting metadata for 0x3ecd8f1e39f6d1656de6f3d73f0c2aa7e2ae324e
[2022-03-14 08:17:58,740 |   INFO   | user_metadata] Getting metadata for 0x81be7f475e335693fda594abc8b42bb0d873f9a0
[2022-03-14 08:18:03,065 |   INFO   | user_metadata] Getting metadata for 0x5763542e5de5f524037b6c90623d00e0d6099bde
[2022-03-14 08:18:07,614 |   INFO   | user_metadata] Getting metadata for 0xb8b5709d1f161a353bb5e902c0ffd761bc4d8074
[2022-03-14 08:18:11,092 |   INFO   | user_metadata] Getting metadata for 0x8c263cf199881bb0cc9b66b50dd7d96212a26c1a
[2022-03-14 08:18:13,299 |   INFO   | user_metadata] Getting metadata for 0xeea43b892d4593e7c44530db1f75b0519db0bd50
[2022-03-14 08:18:17,374 |   INFO   | user_metadata] Getting metadata for 0x6fdc859bfad3bc680647c8c58530faa039e1fc03
[2022-03-14 08:18:20,871 |   INFO   | user_metadata] Getting metadata for 0xc41a84d016b1391fa0f4048d37d3131988412360
[2022-03-14 08:18:23,702 |   INFO   | user_metadata] Getting metadata for 0x7811c6a535ddff8f86bfdeade882e744bc9fe380
[2022-03-14 08:18:26,761 |   INFO   | user_metadata] Getting metadata for 0x01c20350ad8f434bedf6ea901203ac4cf7bca295
[2022-03-14 08:18:30,449 |   INFO   | user_metadata] Getting metadata for 0xa6e2dc44418f5ad213c86db4dbb203a59d13c49f
[2022-03-14 08:18:33,131 |   INFO   | user_metadata] Getting metadata for 0x3c1814c7732bb3899b0ff153b74d8332fcdf0eb8
[2022-03-14 08:18:35,376 |   INFO   | user_metadata] Getting metadata for 0xf7922cc344742fdb8c332ee3a4a25d3fb0a8d5b9
[2022-03-14 08:18:38,083 |   INFO   | user_metadata] Getting metadata for 0x10a2dfb788a57587e6dead219fb2829b8ead9d7b
[2022-03-14 08:18:41,730 |   INFO   | user_metadata] Getting metadata for 0xcdae1bab521e6ad0756f41166e1ac68d4b5ba55a
[2022-03-14 08:18:45,845 |   INFO   | user_metadata] Getting metadata for 0xf98c3c402f9db363d92e9bb15afabfb9c0290114
[2022-03-14 08:18:49,531 |   INFO   | user_metadata] Getting metadata for 0x336a447b2e382dde1cff3532c8218e1f57757a7d
[2022-03-14 08:18:52,048 |   INFO   | user_metadata] Getting metadata for 0xf5a9288eb6e86a3fcb717e7f13475d947f459e3a
[2022-03-14 08:18:55,172 |   INFO   | user_metadata] Getting metadata for 0x8ad272ac86c6c88683d9a60eb8ed57e6c304bb0c
[2022-03-14 08:18:58,880 |   INFO   | user_metadata] Getting metadata for 0xc72aed14386158960d0e93fecb83642e68482e4b
[2022-03-14 08:19:01,627 |   INFO   | user_metadata] Getting metadata for 0x7f931ec7fab3abf3a17a669f55d85bb6516c7e08
[2022-03-14 08:19:05,012 |   INFO   | user_metadata] Getting metadata for 0x0000000000000000000000000000000000080085
[2022-03-14 08:19:09,131 |   INFO   | user_metadata] Getting metadata for 0x695589d2bc5a63db1e830b1da7a07de73e58c6a8
[2022-03-14 08:19:11,492 |   INFO   | user_metadata] Getting metadata for 0x6027b4c9ad98ad5dc9ee984ed699a2079d401416
[2022-03-14 08:19:14,617 |   INFO   | user_metadata] Getting metadata for 0x2a1ca52f11a7f0aa923a6739d49c69004c7246e1
[2022-03-14 08:19:18,665 |   INFO   | user_metadata] Getting metadata for 0x65e45efbb8f8b89320d401addeb7bee7d62db5cf
[2022-03-14 08:19:22,063 |   INFO   | user_metadata] Getting metadata for 0xe7bd8a7c642e807b820c483f87b28f11a796fb37
[2022-03-14 08:19:24,636 |   INFO   | user_metadata] Getting metadata for 0x1ad60130a2528c6f73a8c6e50758532949627dfd
[2022-03-14 08:19:29,250 |   INFO   | user_metadata] Getting metadata for 0x09fe5f0236f0ea5d930197dce254d77b04128075
[2022-03-14 08:19:33,844 |   INFO   | user_metadata] Getting metadata for 0x17963290db8c30552d0cfa2a6453ff20a28c31a2
[2022-03-14 08:19:38,768 |   INFO   | user_metadata] Getting metadata for 0x0000feed00feed00000000feed0000000feed000
[2022-03-14 08:19:42,482 |   INFO   | user_metadata] Getting metadata for 0xa71410d2b0882c6416edd918a7ac51c492ee8d82
[2022-03-14 08:19:46,269 |   INFO   | user_metadata] Getting metadata for 0x3811866a85b0e42b437b36bb4fd2f05e4c3b16f8
[2022-03-14 08:19:49,545 |   INFO   | user_metadata] Getting metadata for 0xa6373078965435bb9181acb5e54d28cd67f8113f
[2022-03-14 08:19:51,755 |   INFO   | user_metadata] Getting metadata for 0xab93f992d9737bd740113643e79fe9f8b6b34696
[2022-03-14 08:19:55,312 |   INFO   | user_metadata] Getting metadata for 0x8f808ae932e3978737952b111bd1331e051796e1
[2022-03-14 08:19:58,931 |   INFO   | user_metadata] Getting metadata for 0x5f20abebe0ba11a9dc0f08e654e416bbee8979f9
[2022-03-14 08:20:02,478 |   INFO   | user_metadata] Getting metadata for 0x7500935c3c34d0d48e9c388b3dffa0abbda52633
[2022-03-14 08:20:04,547 |   INFO   | user_metadata] Getting metadata for 0x073ff66ec93c4ddd98edafeaecd677a7ef61f000
[2022-03-14 08:20:07,836 |   INFO   | user_metadata] Getting metadata for 0x3926450a0d23a0e1fcdff72d0a9660b7fd353743
[2022-03-14 08:20:09,699 |   INFO   | user_metadata] Getting metadata for 0x4be52934b8464b887a2ff04aa02fa1a3fb9584a5
[2022-03-14 08:20:12,192 |   INFO   | user_metadata] Getting metadata for 0x35f0686c63f50707ea3b5bace186938e4e19f03a
[2022-03-14 08:20:15,547 |   INFO   | user_metadata] Getting metadata for 0x255fcbadead80945b733ff6040c466fed277b8db
[2022-03-14 08:20:19,533 |   INFO   | user_metadata] Getting metadata for 0x052564eb0fd8b340803df55def89c25c432f43f4
[2022-03-14 08:20:23,593 |   INFO   | user_metadata] Getting metadata for 0x0845fc89c51b2bcd1c3b0db9dbca497d641ec7d3
[2022-03-14 08:20:26,123 |   INFO   | user_metadata] Getting metadata for 0xd6a6f4c84abd6aa45150905c25158c971fee0010
[2022-03-14 08:20:27,485 |   INFO   | user_metadata] Getting metadata for 0x1d7e43bf140451c9a28ac551d70f25a69795767b
[2022-03-14 08:20:30,183 |   INFO   | user_metadata] Getting metadata for 0x6714de8aa0db267552eb5421167f5d77f0c05c6d
[2022-03-14 08:20:34,042 |   INFO   | user_metadata] Getting metadata for 0x56340c11d6f522eaaa0043dfe5874ff42a38d178
[2022-03-14 08:20:38,231 |   INFO   | user_metadata] Getting metadata for 0xd2b7a9b78667c07ba54d7224c6745d9d781b7cb7
[2022-03-14 08:20:39,123 |  ERROR   | user_metadata] Error getting metadata for 0xd2b7a9b78667c07ba54d7224c6745d9d781b7cb7
Traceback (most recent call last):
  File "user_metadata.py", line 45, in get_metadata
    response = requests.get(url, headers=headers, proxies=proxies, timeout=10)
  File "/home/martin/.local/lib/python3.8/site-packages/requests/api.py", line 75, in get
    return request('get', url, params=params, **kwargs)
  File "/home/martin/.local/lib/python3.8/site-packages/requests/api.py", line 61, in request
    return session.request(method=method, url=url, **kwargs)
  File "/home/martin/.local/lib/python3.8/site-packages/requests/sessions.py", line 529, in request
    resp = self.send(prep, **send_kwargs)
  File "/home/martin/.local/lib/python3.8/site-packages/requests/sessions.py", line 667, in send
    history = [resp for resp in gen]
  File "/home/martin/.local/lib/python3.8/site-packages/requests/sessions.py", line 667, in <listcomp>
    history = [resp for resp in gen]
  File "/home/martin/.local/lib/python3.8/site-packages/requests/sessions.py", line 237, in resolve_redirects
    resp = self.send(
  File "/home/martin/.local/lib/python3.8/site-packages/requests/sessions.py", line 645, in send
    r = adapter.send(request, **kwargs)
  File "/home/martin/.local/lib/python3.8/site-packages/requests/adapters.py", line 440, in send
    resp = conn.urlopen(
  File "/usr/lib/python3/dist-packages/urllib3/connectionpool.py", line 665, in urlopen
    httplib_response = self._make_request(
  File "/usr/lib/python3/dist-packages/urllib3/connectionpool.py", line 421, in _make_request
    six.raise_from(e, None)
  File "<string>", line 3, in raise_from
  File "/usr/lib/python3/dist-packages/urllib3/connectionpool.py", line 416, in _make_request
    httplib_response = conn.getresponse()
  File "/usr/lib/python3.8/http/client.py", line 1348, in getresponse
    response.begin()
  File "/usr/lib/python3.8/http/client.py", line 316, in begin
    version, status, reason = self._read_status()
  File "/usr/lib/python3.8/http/client.py", line 277, in _read_status
    line = str(self.fp.readline(_MAXLINE + 1), "iso-8859-1")
  File "/usr/lib/python3.8/socket.py", line 669, in readinto
    return self._sock.recv_into(b)
  File "/usr/lib/python3.8/ssl.py", line 1241, in recv_into
    return self.read(nbytes, buffer)
  File "/usr/lib/python3.8/ssl.py", line 1099, in read
    return self._sslobj.read(len, buffer)
KeyboardInterrupt
[2022-03-14 08:20:40,114 | CRITICAL | user_metadata] Fatal error
Traceback (most recent call last):
  File "user_metadata.py", line 45, in get_metadata
    response = requests.get(url, headers=headers, proxies=proxies, timeout=10)
  File "/home/martin/.local/lib/python3.8/site-packages/requests/api.py", line 75, in get
    return request('get', url, params=params, **kwargs)
  File "/home/martin/.local/lib/python3.8/site-packages/requests/api.py", line 61, in request
    return session.request(method=method, url=url, **kwargs)
  File "/home/martin/.local/lib/python3.8/site-packages/requests/sessions.py", line 529, in request
    resp = self.send(prep, **send_kwargs)
  File "/home/martin/.local/lib/python3.8/site-packages/requests/sessions.py", line 667, in send
    history = [resp for resp in gen]
  File "/home/martin/.local/lib/python3.8/site-packages/requests/sessions.py", line 667, in <listcomp>
    history = [resp for resp in gen]
  File "/home/martin/.local/lib/python3.8/site-packages/requests/sessions.py", line 237, in resolve_redirects
    resp = self.send(
  File "/home/martin/.local/lib/python3.8/site-packages/requests/sessions.py", line 645, in send
    r = adapter.send(request, **kwargs)
  File "/home/martin/.local/lib/python3.8/site-packages/requests/adapters.py", line 440, in send
    resp = conn.urlopen(
  File "/usr/lib/python3/dist-packages/urllib3/connectionpool.py", line 665, in urlopen
    httplib_response = self._make_request(
  File "/usr/lib/python3/dist-packages/urllib3/connectionpool.py", line 421, in _make_request
    six.raise_from(e, None)
  File "<string>", line 3, in raise_from
  File "/usr/lib/python3/dist-packages/urllib3/connectionpool.py", line 416, in _make_request
    httplib_response = conn.getresponse()
  File "/usr/lib/python3.8/http/client.py", line 1348, in getresponse
    response.begin()
  File "/usr/lib/python3.8/http/client.py", line 316, in begin
    version, status, reason = self._read_status()
  File "/usr/lib/python3.8/http/client.py", line 277, in _read_status
    line = str(self.fp.readline(_MAXLINE + 1), "iso-8859-1")
  File "/usr/lib/python3.8/socket.py", line 669, in readinto
    return self._sock.recv_into(b)
  File "/usr/lib/python3.8/ssl.py", line 1241, in recv_into
    return self.read(nbytes, buffer)
  File "/usr/lib/python3.8/ssl.py", line 1099, in read
    return self._sslobj.read(len, buffer)
KeyboardInterrupt

During handling of the above exception, another exception occurred:

Traceback (most recent call last):
  File "user_metadata.py", line 103, in <module>
    main()
  File "user_metadata.py", line 95, in main
    metadata = get_metadata(username)
  File "user_metadata.py", line 68, in get_metadata
    sleep(10)
KeyboardInterrupt
[2022-03-22 06:34:37,418 |   INFO   | user_metadata] Starting
[2022-03-22 06:34:37,418 |   INFO   | user_metadata] Loaded 1498 usernames
[2022-03-22 06:34:37,418 |   INFO   | user_metadata] Getting metadata for 0x482914ce89836db864987707ac8d96e965419efc
[2022-03-22 06:34:47,466 |  ERROR   | user_metadata] Proxy error
[2022-03-22 06:34:49,460 | CRITICAL | user_metadata] Fatal error
Traceback (most recent call last):
  File "/home/junyuyang/anaconda3/envs/etl/lib/python3.7/site-packages/urllib3/connectionpool.py", line 700, in urlopen
    self._prepare_proxy(conn)
  File "/home/junyuyang/anaconda3/envs/etl/lib/python3.7/site-packages/urllib3/connectionpool.py", line 994, in _prepare_proxy
    conn.connect()
  File "/home/junyuyang/anaconda3/envs/etl/lib/python3.7/site-packages/urllib3/connection.py", line 364, in connect
    conn = self._connect_tls_proxy(hostname, conn)
  File "/home/junyuyang/anaconda3/envs/etl/lib/python3.7/site-packages/urllib3/connection.py", line 507, in _connect_tls_proxy
    ssl_context=ssl_context,
  File "/home/junyuyang/anaconda3/envs/etl/lib/python3.7/site-packages/urllib3/util/ssl_.py", line 453, in ssl_wrap_socket
    ssl_sock = _ssl_wrap_socket_impl(sock, context, tls_in_tls)
  File "/home/junyuyang/anaconda3/envs/etl/lib/python3.7/site-packages/urllib3/util/ssl_.py", line 495, in _ssl_wrap_socket_impl
    return ssl_context.wrap_socket(sock)
  File "/home/junyuyang/anaconda3/envs/etl/lib/python3.7/ssl.py", line 423, in wrap_socket
    session=session
  File "/home/junyuyang/anaconda3/envs/etl/lib/python3.7/ssl.py", line 870, in _create
    self.do_handshake()
  File "/home/junyuyang/anaconda3/envs/etl/lib/python3.7/ssl.py", line 1139, in do_handshake
    self._sslobj.do_handshake()
socket.timeout: _ssl.c:1074: The handshake operation timed out

During handling of the above exception, another exception occurred:

Traceback (most recent call last):
  File "/home/junyuyang/anaconda3/envs/etl/lib/python3.7/site-packages/requests/adapters.py", line 450, in send
    timeout=timeout
  File "/home/junyuyang/anaconda3/envs/etl/lib/python3.7/site-packages/urllib3/connectionpool.py", line 786, in urlopen
    method, url, error=e, _pool=self, _stacktrace=sys.exc_info()[2]
  File "/home/junyuyang/anaconda3/envs/etl/lib/python3.7/site-packages/urllib3/util/retry.py", line 592, in increment
    raise MaxRetryError(_pool, url, error or ResponseError(cause))
urllib3.exceptions.MaxRetryError: HTTPSConnectionPool(host='opensea.io', port=443): Max retries exceeded with url: /0x482914ce89836db864987707ac8d96e965419efc (Caused by ProxyError('Cannot connect to proxy.', timeout('_ssl.c:1074: The handshake operation timed out')))

During handling of the above exception, another exception occurred:

Traceback (most recent call last):
  File "user_metadata.py", line 45, in get_metadata
    response = requests.get(url, headers=headers, proxies=proxies, timeout=10)
  File "/home/junyuyang/anaconda3/envs/etl/lib/python3.7/site-packages/requests/api.py", line 75, in get
    return request('get', url, params=params, **kwargs)
  File "/home/junyuyang/anaconda3/envs/etl/lib/python3.7/site-packages/requests/api.py", line 61, in request
    return session.request(method=method, url=url, **kwargs)
  File "/home/junyuyang/anaconda3/envs/etl/lib/python3.7/site-packages/requests/sessions.py", line 529, in request
    resp = self.send(prep, **send_kwargs)
  File "/home/junyuyang/anaconda3/envs/etl/lib/python3.7/site-packages/requests/sessions.py", line 645, in send
    r = adapter.send(request, **kwargs)
  File "/home/junyuyang/anaconda3/envs/etl/lib/python3.7/site-packages/requests/adapters.py", line 513, in send
    raise ProxyError(e, request=request)
requests.exceptions.ProxyError: HTTPSConnectionPool(host='opensea.io', port=443): Max retries exceeded with url: /0x482914ce89836db864987707ac8d96e965419efc (Caused by ProxyError('Cannot connect to proxy.', timeout('_ssl.c:1074: The handshake operation timed out')))

During handling of the above exception, another exception occurred:

Traceback (most recent call last):
  File "user_metadata.py", line 103, in <module>
    main()
  File "user_metadata.py", line 95, in main
    metadata = get_metadata(username)
  File "user_metadata.py", line 64, in get_metadata
    sleep(10)
KeyboardInterrupt
[2022-03-22 06:41:59,278 |   INFO   | user_metadata] Starting
[2022-03-22 06:41:59,280 |   INFO   | user_metadata] Loaded 1498 usernames
[2022-03-22 06:41:59,280 |   INFO   | user_metadata] Getting metadata for 0x482914ce89836db864987707ac8d96e965419efc
[2022-03-22 06:42:01,418 |   INFO   | user_metadata] Getting metadata for 0xe7079eec020ddfc3f1c0abe1d946c55e6ed30eb3
[2022-03-22 06:42:05,044 |   INFO   | user_metadata] Getting metadata for 0x8bbc693d042cea740e4ff01d7e0efb36110c36bf
[2022-03-22 06:42:05,770 |  ERROR   | user_metadata] Error getting metadata for 0x8bbc693d042cea740e4ff01d7e0efb36110c36bf
Traceback (most recent call last):
  File "user_metadata.py", line 45, in get_metadata
    response = requests.get(url, headers=headers, proxies=proxies, timeout=10)
  File "/usr/lib/python3/dist-packages/requests/api.py", line 75, in get
    return request('get', url, params=params, **kwargs)
  File "/usr/lib/python3/dist-packages/requests/api.py", line 60, in request
    return session.request(method=method, url=url, **kwargs)
  File "/usr/lib/python3/dist-packages/requests/sessions.py", line 533, in request
    resp = self.send(prep, **send_kwargs)
  File "/usr/lib/python3/dist-packages/requests/sessions.py", line 668, in send
    history = [resp for resp in gen] if allow_redirects else []
  File "/usr/lib/python3/dist-packages/requests/sessions.py", line 668, in <listcomp>
    history = [resp for resp in gen] if allow_redirects else []
  File "/usr/lib/python3/dist-packages/requests/sessions.py", line 239, in resolve_redirects
    resp = self.send(
  File "/usr/lib/python3/dist-packages/requests/sessions.py", line 646, in send
    r = adapter.send(request, **kwargs)
  File "/usr/lib/python3/dist-packages/requests/adapters.py", line 439, in send
    resp = conn.urlopen(
  File "/usr/lib/python3/dist-packages/urllib3/connectionpool.py", line 665, in urlopen
    httplib_response = self._make_request(
  File "/usr/lib/python3/dist-packages/urllib3/connectionpool.py", line 421, in _make_request
    six.raise_from(e, None)
  File "<string>", line 3, in raise_from
  File "/usr/lib/python3/dist-packages/urllib3/connectionpool.py", line 416, in _make_request
    httplib_response = conn.getresponse()
  File "/usr/lib/python3.8/http/client.py", line 1348, in getresponse
    response.begin()
  File "/usr/lib/python3.8/http/client.py", line 316, in begin
    version, status, reason = self._read_status()
  File "/usr/lib/python3.8/http/client.py", line 277, in _read_status
    line = str(self.fp.readline(_MAXLINE + 1), "iso-8859-1")
  File "/usr/lib/python3.8/socket.py", line 669, in readinto
    return self._sock.recv_into(b)
  File "/usr/lib/python3/dist-packages/urllib3/contrib/pyopenssl.py", line 325, in recv_into
    if not util.wait_for_read(self.socket, self.socket.gettimeout()):
  File "/usr/lib/python3/dist-packages/urllib3/util/wait.py", line 146, in wait_for_read
    return wait_for_socket(sock, read=True, timeout=timeout)
  File "/usr/lib/python3/dist-packages/urllib3/util/wait.py", line 107, in poll_wait_for_socket
    return bool(_retry_on_intr(do_poll, timeout))
  File "/usr/lib/python3/dist-packages/urllib3/util/wait.py", line 43, in _retry_on_intr
    return fn(timeout)
  File "/usr/lib/python3/dist-packages/urllib3/util/wait.py", line 105, in do_poll
    return poll_obj.poll(t)
KeyboardInterrupt
[2022-03-22 06:42:05,970 | CRITICAL | user_metadata] Fatal error
Traceback (most recent call last):
  File "user_metadata.py", line 45, in get_metadata
    response = requests.get(url, headers=headers, proxies=proxies, timeout=10)
  File "/usr/lib/python3/dist-packages/requests/api.py", line 75, in get
    return request('get', url, params=params, **kwargs)
  File "/usr/lib/python3/dist-packages/requests/api.py", line 60, in request
    return session.request(method=method, url=url, **kwargs)
  File "/usr/lib/python3/dist-packages/requests/sessions.py", line 533, in request
    resp = self.send(prep, **send_kwargs)
  File "/usr/lib/python3/dist-packages/requests/sessions.py", line 668, in send
    history = [resp for resp in gen] if allow_redirects else []
  File "/usr/lib/python3/dist-packages/requests/sessions.py", line 668, in <listcomp>
    history = [resp for resp in gen] if allow_redirects else []
  File "/usr/lib/python3/dist-packages/requests/sessions.py", line 239, in resolve_redirects
    resp = self.send(
  File "/usr/lib/python3/dist-packages/requests/sessions.py", line 646, in send
    r = adapter.send(request, **kwargs)
  File "/usr/lib/python3/dist-packages/requests/adapters.py", line 439, in send
    resp = conn.urlopen(
  File "/usr/lib/python3/dist-packages/urllib3/connectionpool.py", line 665, in urlopen
    httplib_response = self._make_request(
  File "/usr/lib/python3/dist-packages/urllib3/connectionpool.py", line 421, in _make_request
    six.raise_from(e, None)
  File "<string>", line 3, in raise_from
  File "/usr/lib/python3/dist-packages/urllib3/connectionpool.py", line 416, in _make_request
    httplib_response = conn.getresponse()
  File "/usr/lib/python3.8/http/client.py", line 1348, in getresponse
    response.begin()
  File "/usr/lib/python3.8/http/client.py", line 316, in begin
    version, status, reason = self._read_status()
  File "/usr/lib/python3.8/http/client.py", line 277, in _read_status
    line = str(self.fp.readline(_MAXLINE + 1), "iso-8859-1")
  File "/usr/lib/python3.8/socket.py", line 669, in readinto
    return self._sock.recv_into(b)
  File "/usr/lib/python3/dist-packages/urllib3/contrib/pyopenssl.py", line 325, in recv_into
    if not util.wait_for_read(self.socket, self.socket.gettimeout()):
  File "/usr/lib/python3/dist-packages/urllib3/util/wait.py", line 146, in wait_for_read
    return wait_for_socket(sock, read=True, timeout=timeout)
  File "/usr/lib/python3/dist-packages/urllib3/util/wait.py", line 107, in poll_wait_for_socket
    return bool(_retry_on_intr(do_poll, timeout))
  File "/usr/lib/python3/dist-packages/urllib3/util/wait.py", line 43, in _retry_on_intr
    return fn(timeout)
  File "/usr/lib/python3/dist-packages/urllib3/util/wait.py", line 105, in do_poll
    return poll_obj.poll(t)
KeyboardInterrupt

During handling of the above exception, another exception occurred:

Traceback (most recent call last):
  File "user_metadata.py", line 103, in <module>
    main()
  File "user_metadata.py", line 95, in main
    metadata = get_metadata(username)
  File "user_metadata.py", line 68, in get_metadata
    sleep(10)
KeyboardInterrupt
[2022-03-22 07:16:51,748 |   INFO   | user_metadata] Starting
[2022-03-22 07:16:51,748 |   INFO   | user_metadata] Loaded 1498 usernames
[2022-03-22 07:16:51,748 |   INFO   | user_metadata] Getting metadata for 0x482914ce89836db864987707ac8d96e965419efc
[2022-03-22 07:17:01,793 |  ERROR   | user_metadata] Proxy error
[2022-03-22 07:17:21,841 |  ERROR   | user_metadata] Proxy error
[2022-03-22 07:17:26,564 | CRITICAL | user_metadata] Fatal error
Traceback (most recent call last):
  File "/home/junyuyang/virtual_env/etl/lib/python3.8/site-packages/urllib3/connectionpool.py", line 700, in urlopen
    self._prepare_proxy(conn)
  File "/home/junyuyang/virtual_env/etl/lib/python3.8/site-packages/urllib3/connectionpool.py", line 994, in _prepare_proxy
    conn.connect()
  File "/home/junyuyang/virtual_env/etl/lib/python3.8/site-packages/urllib3/connection.py", line 364, in connect
    self.sock = conn = self._connect_tls_proxy(hostname, conn)
  File "/home/junyuyang/virtual_env/etl/lib/python3.8/site-packages/urllib3/connection.py", line 499, in _connect_tls_proxy
    socket = ssl_wrap_socket(
  File "/home/junyuyang/virtual_env/etl/lib/python3.8/site-packages/urllib3/util/ssl_.py", line 453, in ssl_wrap_socket
    ssl_sock = _ssl_wrap_socket_impl(sock, context, tls_in_tls)
  File "/home/junyuyang/virtual_env/etl/lib/python3.8/site-packages/urllib3/util/ssl_.py", line 495, in _ssl_wrap_socket_impl
    return ssl_context.wrap_socket(sock)
  File "/usr/lib/python3.8/ssl.py", line 500, in wrap_socket
    return self.sslsocket_class._create(
  File "/usr/lib/python3.8/ssl.py", line 1040, in _create
    self.do_handshake()
  File "/usr/lib/python3.8/ssl.py", line 1309, in do_handshake
    self._sslobj.do_handshake()
socket.timeout: _ssl.c:1114: The handshake operation timed out

During handling of the above exception, another exception occurred:

Traceback (most recent call last):
  File "/home/junyuyang/virtual_env/etl/lib/python3.8/site-packages/requests/adapters.py", line 440, in send
    resp = conn.urlopen(
  File "/home/junyuyang/virtual_env/etl/lib/python3.8/site-packages/urllib3/connectionpool.py", line 785, in urlopen
    retries = retries.increment(
  File "/home/junyuyang/virtual_env/etl/lib/python3.8/site-packages/urllib3/util/retry.py", line 592, in increment
    raise MaxRetryError(_pool, url, error or ResponseError(cause))
urllib3.exceptions.MaxRetryError: HTTPSConnectionPool(host='opensea.io', port=443): Max retries exceeded with url: /0x482914ce89836db864987707ac8d96e965419efc (Caused by ProxyError('Cannot connect to proxy.', timeout('_ssl.c:1114: The handshake operation timed out')))

During handling of the above exception, another exception occurred:

Traceback (most recent call last):
  File "user_metadata.py", line 45, in get_metadata
    response = requests.get(url, headers=headers, proxies=proxies, timeout=10)
  File "/home/junyuyang/virtual_env/etl/lib/python3.8/site-packages/requests/api.py", line 75, in get
    return request('get', url, params=params, **kwargs)
  File "/home/junyuyang/virtual_env/etl/lib/python3.8/site-packages/requests/api.py", line 61, in request
    return session.request(method=method, url=url, **kwargs)
  File "/home/junyuyang/virtual_env/etl/lib/python3.8/site-packages/requests/sessions.py", line 529, in request
    resp = self.send(prep, **send_kwargs)
  File "/home/junyuyang/virtual_env/etl/lib/python3.8/site-packages/requests/sessions.py", line 645, in send
    r = adapter.send(request, **kwargs)
  File "/home/junyuyang/virtual_env/etl/lib/python3.8/site-packages/requests/adapters.py", line 513, in send
    raise ProxyError(e, request=request)
requests.exceptions.ProxyError: HTTPSConnectionPool(host='opensea.io', port=443): Max retries exceeded with url: /0x482914ce89836db864987707ac8d96e965419efc (Caused by ProxyError('Cannot connect to proxy.', timeout('_ssl.c:1114: The handshake operation timed out')))

During handling of the above exception, another exception occurred:

Traceback (most recent call last):
  File "user_metadata.py", line 103, in <module>
    main()
  File "user_metadata.py", line 95, in main
    metadata = get_metadata(username)
  File "user_metadata.py", line 64, in get_metadata
    sleep(10)
KeyboardInterrupt
