[2022-03-14 06:29:30,038 |   INFO   | user_metadata] Starting
[2022-03-14 06:29:30,039 |   INFO   | user_metadata] Loaded 1498 usernames
[2022-03-14 06:29:30,039 |   INFO   | user_metadata] Getting metadata for 0x482914ce89836db864987707ac8d96e965419efc
[2022-03-14 06:29:40,196 |  ERROR   | user_metadata] Proxy error
[2022-03-14 06:30:00,253 |  ERROR   | user_metadata] Proxy error
[2022-03-14 06:30:20,311 |  ERROR   | user_metadata] Proxy error
[2022-03-14 06:30:40,360 |  ERROR   | user_metadata] Proxy error
[2022-03-14 06:31:00,418 |  ERROR   | user_metadata] Proxy error
[2022-03-14 06:31:20,473 |  ERROR   | user_metadata] Proxy error
[2022-03-14 06:31:31,878 |  ERROR   | user_metadata] Error getting metadata for 0x482914ce89836db864987707ac8d96e965419efc
Traceback (most recent call last):
  File "user_metadata.py", line 45, in get_metadata
    response = requests.get(url, headers=headers, proxies=proxies, timeout=10)
  File "/home/junyuyang/anaconda3/envs/etl/lib/python3.7/site-packages/requests/api.py", line 75, in get
    return request('get', url, params=params, **kwargs)
  File "/home/junyuyang/anaconda3/envs/etl/lib/python3.7/site-packages/requests/api.py", line 61, in request
    return session.request(method=method, url=url, **kwargs)
  File "/home/junyuyang/anaconda3/envs/etl/lib/python3.7/site-packages/requests/sessions.py", line 542, in request
    resp = self.send(prep, **send_kwargs)
  File "/home/junyuyang/anaconda3/envs/etl/lib/python3.7/site-packages/requests/sessions.py", line 655, in send
    r = adapter.send(request, **kwargs)
  File "/home/junyuyang/anaconda3/envs/etl/lib/python3.7/site-packages/requests/adapters.py", line 449, in send
    timeout=timeout
  File "/home/junyuyang/anaconda3/envs/etl/lib/python3.7/site-packages/urllib3/connectionpool.py", line 700, in urlopen
    self._prepare_proxy(conn)
  File "/home/junyuyang/anaconda3/envs/etl/lib/python3.7/site-packages/urllib3/connectionpool.py", line 994, in _prepare_proxy
    conn.connect()
  File "/home/junyuyang/anaconda3/envs/etl/lib/python3.7/site-packages/urllib3/connection.py", line 364, in connect
    conn = self._connect_tls_proxy(hostname, conn)
  File "/home/junyuyang/anaconda3/envs/etl/lib/python3.7/site-packages/urllib3/connection.py", line 507, in _connect_tls_proxy
    ssl_context=ssl_context,
  File "/home/junyuyang/anaconda3/envs/etl/lib/python3.7/site-packages/urllib3/util/ssl_.py", line 453, in ssl_wrap_socket
    ssl_sock = _ssl_wrap_socket_impl(sock, context, tls_in_tls)
  File "/home/junyuyang/anaconda3/envs/etl/lib/python3.7/site-packages/urllib3/util/ssl_.py", line 495, in _ssl_wrap_socket_impl
    return ssl_context.wrap_socket(sock)
  File "/home/junyuyang/anaconda3/envs/etl/lib/python3.7/ssl.py", line 423, in wrap_socket
    session=session
  File "/home/junyuyang/anaconda3/envs/etl/lib/python3.7/ssl.py", line 870, in _create
    self.do_handshake()
  File "/home/junyuyang/anaconda3/envs/etl/lib/python3.7/ssl.py", line 1139, in do_handshake
    self._sslobj.do_handshake()
KeyboardInterrupt
[2022-03-14 06:31:33,489 | CRITICAL | user_metadata] Fatal error
Traceback (most recent call last):
  File "user_metadata.py", line 45, in get_metadata
    response = requests.get(url, headers=headers, proxies=proxies, timeout=10)
  File "/home/junyuyang/anaconda3/envs/etl/lib/python3.7/site-packages/requests/api.py", line 75, in get
    return request('get', url, params=params, **kwargs)
  File "/home/junyuyang/anaconda3/envs/etl/lib/python3.7/site-packages/requests/api.py", line 61, in request
    return session.request(method=method, url=url, **kwargs)
  File "/home/junyuyang/anaconda3/envs/etl/lib/python3.7/site-packages/requests/sessions.py", line 542, in request
    resp = self.send(prep, **send_kwargs)
  File "/home/junyuyang/anaconda3/envs/etl/lib/python3.7/site-packages/requests/sessions.py", line 655, in send
    r = adapter.send(request, **kwargs)
  File "/home/junyuyang/anaconda3/envs/etl/lib/python3.7/site-packages/requests/adapters.py", line 449, in send
    timeout=timeout
  File "/home/junyuyang/anaconda3/envs/etl/lib/python3.7/site-packages/urllib3/connectionpool.py", line 700, in urlopen
    self._prepare_proxy(conn)
  File "/home/junyuyang/anaconda3/envs/etl/lib/python3.7/site-packages/urllib3/connectionpool.py", line 994, in _prepare_proxy
    conn.connect()
  File "/home/junyuyang/anaconda3/envs/etl/lib/python3.7/site-packages/urllib3/connection.py", line 364, in connect
    conn = self._connect_tls_proxy(hostname, conn)
  File "/home/junyuyang/anaconda3/envs/etl/lib/python3.7/site-packages/urllib3/connection.py", line 507, in _connect_tls_proxy
    ssl_context=ssl_context,
  File "/home/junyuyang/anaconda3/envs/etl/lib/python3.7/site-packages/urllib3/util/ssl_.py", line 453, in ssl_wrap_socket
    ssl_sock = _ssl_wrap_socket_impl(sock, context, tls_in_tls)
  File "/home/junyuyang/anaconda3/envs/etl/lib/python3.7/site-packages/urllib3/util/ssl_.py", line 495, in _ssl_wrap_socket_impl
    return ssl_context.wrap_socket(sock)
  File "/home/junyuyang/anaconda3/envs/etl/lib/python3.7/ssl.py", line 423, in wrap_socket
    session=session
  File "/home/junyuyang/anaconda3/envs/etl/lib/python3.7/ssl.py", line 870, in _create
    self.do_handshake()
  File "/home/junyuyang/anaconda3/envs/etl/lib/python3.7/ssl.py", line 1139, in do_handshake
    self._sslobj.do_handshake()
KeyboardInterrupt

During handling of the above exception, another exception occurred:

Traceback (most recent call last):
  File "user_metadata.py", line 103, in <module>
    try:
  File "user_metadata.py", line 95, in main
    logger.info(f"Getting metadata for {username}")
  File "user_metadata.py", line 68, in get_metadata
    logger.error(f"Error getting metadata for {username}", exc_info=True)
KeyboardInterrupt
[2022-03-14 06:31:34,656 |   INFO   | user_metadata] Starting
[2022-03-14 06:31:34,656 |   INFO   | user_metadata] Loaded 1498 usernames
[2022-03-14 06:31:34,656 |   INFO   | user_metadata] Getting metadata for 0x482914ce89836db864987707ac8d96e965419efc
[2022-03-14 06:31:44,704 |  ERROR   | user_metadata] Proxy error
[2022-03-14 06:31:47,910 | CRITICAL | user_metadata] Fatal error
Traceback (most recent call last):
  File "/home/junyuyang/anaconda3/envs/etl/lib/python3.7/site-packages/urllib3/connectionpool.py", line 700, in urlopen
    self._prepare_proxy(conn)
  File "/home/junyuyang/anaconda3/envs/etl/lib/python3.7/site-packages/urllib3/connectionpool.py", line 994, in _prepare_proxy
    conn.connect()
  File "/home/junyuyang/anaconda3/envs/etl/lib/python3.7/site-packages/urllib3/connection.py", line 364, in connect
    conn = self._connect_tls_proxy(hostname, conn)
  File "/home/junyuyang/anaconda3/envs/etl/lib/python3.7/site-packages/urllib3/connection.py", line 507, in _connect_tls_proxy
    ssl_context=ssl_context,
  File "/home/junyuyang/anaconda3/envs/etl/lib/python3.7/site-packages/urllib3/util/ssl_.py", line 453, in ssl_wrap_socket
    ssl_sock = _ssl_wrap_socket_impl(sock, context, tls_in_tls)
  File "/home/junyuyang/anaconda3/envs/etl/lib/python3.7/site-packages/urllib3/util/ssl_.py", line 495, in _ssl_wrap_socket_impl
    return ssl_context.wrap_socket(sock)
  File "/home/junyuyang/anaconda3/envs/etl/lib/python3.7/ssl.py", line 423, in wrap_socket
    session=session
  File "/home/junyuyang/anaconda3/envs/etl/lib/python3.7/ssl.py", line 870, in _create
    self.do_handshake()
  File "/home/junyuyang/anaconda3/envs/etl/lib/python3.7/ssl.py", line 1139, in do_handshake
    self._sslobj.do_handshake()
socket.timeout: _ssl.c:1074: The handshake operation timed out

During handling of the above exception, another exception occurred:

Traceback (most recent call last):
  File "/home/junyuyang/anaconda3/envs/etl/lib/python3.7/site-packages/requests/adapters.py", line 449, in send
    timeout=timeout
  File "/home/junyuyang/anaconda3/envs/etl/lib/python3.7/site-packages/urllib3/connectionpool.py", line 786, in urlopen
    method, url, error=e, _pool=self, _stacktrace=sys.exc_info()[2]
  File "/home/junyuyang/anaconda3/envs/etl/lib/python3.7/site-packages/urllib3/util/retry.py", line 592, in increment
    raise MaxRetryError(_pool, url, error or ResponseError(cause))
urllib3.exceptions.MaxRetryError: HTTPSConnectionPool(host='opensea.io', port=443): Max retries exceeded with url: /0x482914ce89836db864987707ac8d96e965419efc (Caused by ProxyError('Cannot connect to proxy.', timeout('_ssl.c:1074: The handshake operation timed out')))

During handling of the above exception, another exception occurred:

Traceback (most recent call last):
  File "user_metadata.py", line 45, in get_metadata
    response = requests.get(url, headers=headers, proxies=proxies, timeout=10)
  File "/home/junyuyang/anaconda3/envs/etl/lib/python3.7/site-packages/requests/api.py", line 75, in get
    return request('get', url, params=params, **kwargs)
  File "/home/junyuyang/anaconda3/envs/etl/lib/python3.7/site-packages/requests/api.py", line 61, in request
    return session.request(method=method, url=url, **kwargs)
  File "/home/junyuyang/anaconda3/envs/etl/lib/python3.7/site-packages/requests/sessions.py", line 542, in request
    resp = self.send(prep, **send_kwargs)
  File "/home/junyuyang/anaconda3/envs/etl/lib/python3.7/site-packages/requests/sessions.py", line 655, in send
    r = adapter.send(request, **kwargs)
  File "/home/junyuyang/anaconda3/envs/etl/lib/python3.7/site-packages/requests/adapters.py", line 510, in send
    raise ProxyError(e, request=request)
requests.exceptions.ProxyError: HTTPSConnectionPool(host='opensea.io', port=443): Max retries exceeded with url: /0x482914ce89836db864987707ac8d96e965419efc (Caused by ProxyError('Cannot connect to proxy.', timeout('_ssl.c:1074: The handshake operation timed out')))

During handling of the above exception, another exception occurred:

Traceback (most recent call last):
  File "user_metadata.py", line 104, in <module>
    main()
  File "user_metadata.py", line 96, in main
    metadata = get_metadata(username)
  File "user_metadata.py", line 65, in get_metadata
    sleep(10)
KeyboardInterrupt
[2022-03-14 06:34:41,872 |   INFO   | user_metadata] Starting
[2022-03-14 06:34:41,872 |   INFO   | user_metadata] Loaded 1498 usernames
[2022-03-14 06:34:41,872 |   INFO   | user_metadata] Getting metadata for 0x482914ce89836db864987707ac8d96e965419efc
[2022-03-14 06:34:51,921 |  ERROR   | user_metadata] Proxy error
[2022-03-14 06:35:00,325 | CRITICAL | user_metadata] Fatal error
Traceback (most recent call last):
  File "/home/junyuyang/anaconda3/envs/etl/lib/python3.7/site-packages/urllib3/connectionpool.py", line 700, in urlopen
    self._prepare_proxy(conn)
  File "/home/junyuyang/anaconda3/envs/etl/lib/python3.7/site-packages/urllib3/connectionpool.py", line 994, in _prepare_proxy
    conn.connect()
  File "/home/junyuyang/anaconda3/envs/etl/lib/python3.7/site-packages/urllib3/connection.py", line 364, in connect
    conn = self._connect_tls_proxy(hostname, conn)
  File "/home/junyuyang/anaconda3/envs/etl/lib/python3.7/site-packages/urllib3/connection.py", line 507, in _connect_tls_proxy
    ssl_context=ssl_context,
  File "/home/junyuyang/anaconda3/envs/etl/lib/python3.7/site-packages/urllib3/util/ssl_.py", line 453, in ssl_wrap_socket
    ssl_sock = _ssl_wrap_socket_impl(sock, context, tls_in_tls)
  File "/home/junyuyang/anaconda3/envs/etl/lib/python3.7/site-packages/urllib3/util/ssl_.py", line 495, in _ssl_wrap_socket_impl
    return ssl_context.wrap_socket(sock)
  File "/home/junyuyang/anaconda3/envs/etl/lib/python3.7/ssl.py", line 423, in wrap_socket
    session=session
  File "/home/junyuyang/anaconda3/envs/etl/lib/python3.7/ssl.py", line 870, in _create
    self.do_handshake()
  File "/home/junyuyang/anaconda3/envs/etl/lib/python3.7/ssl.py", line 1139, in do_handshake
    self._sslobj.do_handshake()
socket.timeout: _ssl.c:1074: The handshake operation timed out

During handling of the above exception, another exception occurred:

Traceback (most recent call last):
  File "/home/junyuyang/anaconda3/envs/etl/lib/python3.7/site-packages/requests/adapters.py", line 449, in send
    timeout=timeout
  File "/home/junyuyang/anaconda3/envs/etl/lib/python3.7/site-packages/urllib3/connectionpool.py", line 786, in urlopen
    method, url, error=e, _pool=self, _stacktrace=sys.exc_info()[2]
  File "/home/junyuyang/anaconda3/envs/etl/lib/python3.7/site-packages/urllib3/util/retry.py", line 592, in increment
    raise MaxRetryError(_pool, url, error or ResponseError(cause))
urllib3.exceptions.MaxRetryError: HTTPSConnectionPool(host='opensea.io', port=443): Max retries exceeded with url: /0x482914ce89836db864987707ac8d96e965419efc (Caused by ProxyError('Cannot connect to proxy.', timeout('_ssl.c:1074: The handshake operation timed out')))

During handling of the above exception, another exception occurred:

Traceback (most recent call last):
  File "user_metadata.py", line 45, in get_metadata
    response = requests.get(url, headers=headers, proxies=proxies, timeout=10)
  File "/home/junyuyang/anaconda3/envs/etl/lib/python3.7/site-packages/requests/api.py", line 75, in get
    return request('get', url, params=params, **kwargs)
  File "/home/junyuyang/anaconda3/envs/etl/lib/python3.7/site-packages/requests/api.py", line 61, in request
    return session.request(method=method, url=url, **kwargs)
  File "/home/junyuyang/anaconda3/envs/etl/lib/python3.7/site-packages/requests/sessions.py", line 542, in request
    resp = self.send(prep, **send_kwargs)
  File "/home/junyuyang/anaconda3/envs/etl/lib/python3.7/site-packages/requests/sessions.py", line 655, in send
    r = adapter.send(request, **kwargs)
  File "/home/junyuyang/anaconda3/envs/etl/lib/python3.7/site-packages/requests/adapters.py", line 510, in send
    raise ProxyError(e, request=request)
requests.exceptions.ProxyError: HTTPSConnectionPool(host='opensea.io', port=443): Max retries exceeded with url: /0x482914ce89836db864987707ac8d96e965419efc (Caused by ProxyError('Cannot connect to proxy.', timeout('_ssl.c:1074: The handshake operation timed out')))

During handling of the above exception, another exception occurred:

Traceback (most recent call last):
  File "user_metadata.py", line 104, in <module>
    main()
  File "user_metadata.py", line 96, in main
    metadata = get_metadata(username)
  File "user_metadata.py", line 65, in get_metadata
    sleep(10)
KeyboardInterrupt
